Workbook

Sheet Fisa
A1: FIȘĂ COMANDĂ | M1: Rev. | N1: Data Rev. | O1: Alege Motivul Reviziei
A2: . | M2: 1
A3: Client: | H3: Tip proiect: | M3: 2
A4: Titlu proiect: | H4: Tip Solicitare: | M4: 3
A5: Nr proiect: | H5: Preluat de: | M5: 4
A6: Data: | H6: Proiectat de: | M6: 5
A8: MATERIALE | F8: ABS (ml)
F9: 22/0.4 | H9: 22/1 | J9: 23/0.8 | L9: 23/2 | N9: 43/1 | P9: 43/1.5 | R9: 43/2
A10: PAL | B10: Decor | C10: Cant. | D10: U.M. | F10: Decor | G10: Cant. | H10: Decor | I10: Cant. | J10: Decor | K10: Cant. | L10: Decor | M10: Cant. | N10: Decor | O10: Cant. | P10: Decor | Q10: Cant. | R10: Decor | S10: Cant.
B11: =IFERROR(INDEX(Deco!$Y$2:$Y$99,_xlfn.AGGREGATE(15,6,ROW(Deco!$Y$2:$Y$99)-ROW(Deco!$Y$2)+1/(Deco!$W$2:$W$99="PAL"),1)),"") | C11: {=IFERROR( IF(D11="buc", IF(B11<>"", INDEX(Deco!$C$2:$C$99, MATCH(1, (Deco!$Y$2:$Y$99=B11)*(Deco!$W$2:$W$99="PAL"), 0)), ""), IF(AND(B11<>"", INDEX(Deco!$W$2:$W$99, MATCH(1, (Deco!$Y$2:$Y$99=B11)*(Deco!$W$2:$W$99="PAL"), 0))="PAL"), INDEX(Deco!$V$2:$V$99, MATCH(1, (Deco!$Y$2:$Y$99=B11)*(Deco!$W$2:$W$99="PAL"), 0)), "") ), "")} | D11: {=IF(I3="Debitare căntuire", IF(OR(RIGHT(B11,1)={"0","1","2","3","4","5","6","7","8","9"},RIGHT(B11,2)="SM",RIGHT(B11,2)="PM",RIGHT(B11,2)="PG",RIGHT(B11,2)="mm",RIGHT(B11,2)="mp",RIGHT(B11,2)="PA",RIGHT(B11,2)="3D"),"buc","mp"), "mp")} -> mp | F11: {=IFERROR(INDEX(Cant!$M$2:$M$99,_xlfn.AGGREGATE(15,6,(ROW(Cant!$M$2:$M$99)-ROW(Cant!$M$2)+1)/((Cant!$M$2:$M$99<>"")*(COUNTIF($F$10:F10,Cant!$M$2:$M$99)=0)),1)),"")} | G11: =IFERROR(IF(AND(F11<>"",SUMIFS(Cant!$I$2:$I$99,Cant!$M$2:$M$99,F11,Cant!$J$2:$J$99,"22/0.4")+SUMIFS(Cant!$I$2:$I$99,Cant!$M$2:$M$99,F11,Cant!$J$2:$J$99,"22/0.5")>0), SUMIFS(Cant!$I$2:$I$99,Cant!$M$2:$M$99,F11,Cant!$J$2:$J$99,"22/0.4") +SUMIFS(Cant!$I$2:$I$99,Cant!$M$2:$M$99,F11,Cant!$J$2:$J$99,"22/0.5"), ""), "") | H11: =CONCATENATE(F11) | I11: =IFERROR( IF(AND(H11<>"", SUMIFS(Cant!$I$2:$I$99,Cant!$M$2:$M$99,H11,Cant!$J$2:$J$99,"22/1.0") +SUMIFS(Cant!$I$2:$I$99,Cant!$M$2:$M$99,H11,Cant!$J$2:$J$99,"23/1.0")>0), SUMIFS(Cant!$I$2:$I$99,Cant!$M$2:$M$99,H11,Cant!$J$2:$J$99,"22/1.0") +SUMIFS(Cant!$I$2:$I$99,Cant!$M$2:$M$99,H11,Cant!$J$2:$J$99,"23/1.0"), ""),"") | J11: =CONCATENATE(F11) | K11: =IFERROR(IF(AND(J11<>"",SUMIFS(Cant!$I$2:$I$99,Cant!$M$2:$M$99,J11,Cant!$J$2:$J$99,"23/0.8")>0),SUMIFS(Cant!$I$2:$I$99,Cant!$M$2:$M$99,J11,Cant!$J$2:$J$99,"23/0.8"),""),"") | L11: =CONCATENATE(F11) | M11: =IFERROR(IF(AND(L11<>"",SUMIFS(Cant!$I$2:$I$99,Cant!$M$2:$M$99,L11,Cant!$J$2:$J$99,"23/2.0")>0),SUMIFS(Cant!$I$2:$I$99,Cant!$M$2:$M$99,L11,Cant!$J$2:$J$99,"23/2.0"),""),"") | N11: =CONCATENATE(F11) | O11: =IFERROR(IF(AND(N11<>"",SUMIFS(Cant!$I$2:$I$99,Cant!$M$2:$M$99,N11,Cant!$J$2:$J$99,"43/1.0")+SUMIFS(Cant!$I$2:$I$99,Cant!$M$2:$M$99,F11,Cant!$J$2:$J$99,"43/0.8")+SUMIFS(Cant!$I$2:$I$99,Cant!$M$2:$M$99,F11,Cant!$J$2:$J$99,"42/1.0")>0),SUMIFS(Cant!$I$2:$I$99,Cant!$M$2:$M$99,N11,Cant!$J$2:$J$99,"43/1.0")+SUMIFS(Cant!$I$2:$I$99,Cant!$M$2:$M$99,N11,Cant!$J$2:$J$99,"43/0.8")++SUMIFS(Cant!$I$2:$I$99,Cant!$M$2:$M$99,F11,Cant!$J$2:$J$99,"42/1.0"),""),"") | P11: =CONCATENATE(F11) | Q11: =IFERROR(IF(AND(P11<>"",SUMIFS(Cant!$I$2:$I$99,Cant!$M$2:$M$99,P11,Cant!$J$2:$J$99,"43/1.5")+SUMIFS(Cant!$I$2:$I$99,Cant!$M$2:$M$99,P11,Cant!$J$2:$J$99,"24/1.5")>0),SUMIFS(Cant!$I$2:$I$99,Cant!$M$2:$M$99,P11,Cant!$J$2:$J$99,"43/1.5")+SUMIFS(Cant!$I$2:$I$99,Cant!$M$2:$M$99,P11,Cant!$J$2:$J$99,"24/1.5"),""),"") | R11: =CONCATENATE(F11) | S11: =IFERROR(IF(AND(R11<>"",SUMIFS(Cant!$I$2:$I$99,Cant!$M$2:$M$99,R11,Cant!$J$2:$J$99,"43/2.0")>0),SUMIFS(Cant!$I$2:$I$99,Cant!$M$2:$M$99,R11,Cant!$J$2:$J$99,"43/2.0"),""),"")
B12: {=IFERROR(_xlfn.SINGLE(INDEX(Deco!$Y$2:$Y$99,_xlfn.AGGREGATE(15,6,ROW(Deco!$Y$2:$Y$99)-ROW(Deco!$Y$2)+1/(Deco!$W$2:$W$99="PAL"),2))),"")} | C12: {=IFERROR( IF(D12="buc", IF(B12<>"", INDEX(Deco!$C$2:$C$99, MATCH(1, (Deco!$Y$2:$Y$99=B12)*(Deco!$W$2:$W$99="PAL"), 0)), ""), IF(AND(B12<>"", INDEX(Deco!$W$2:$W$99, MATCH(1, (Deco!$Y$2:$Y$99=B12)*(Deco!$W$2:$W$99="PAL"), 0))="PAL"), INDEX(Deco!$V$2:$V$99, MATCH(1, (Deco!$Y$2:$Y$99=B12)*(Deco!$W$2:$W$99="PAL"), 0)), "") ), "")} | D12: {=IF(I3="Debitare căntuire", IF(OR(RIGHT(B12,1)={"0","1","2","3","4","5","6","7","8","9"},RIGHT(B12,2)="SM",RIGHT(B12,2)="PM",RIGHT(B12,2)="PG",RIGHT(B12,2)="mm",RIGHT(B12,2)="mp",RIGHT(B12,2)="PA",RIGHT(B12,2)="3D"),"buc","mp"), "mp")} -> mp | F12: {=IFERROR(INDEX(Cant!$M$2:$M$99,_xlfn.AGGREGATE(15,6,(ROW(Cant!$M$2:$M$99)-ROW(Cant!$M$2)+1)/((Cant!$M$2:$M$99<>"")*(COUNTIF($F$10:F11,Cant!$M$2:$M$99)=0)),1)),"")} | G12: =IF(AND(F12<>"",COUNTIF($F$11:F11,F12)>0),"",IFERROR(IF(AND(F12<>"",SUMIFS(Cant!$I$2:$I$99,Cant!$M$2:$M$99,F12,Cant!$J$2:$J$99,"22/0.4") +SUMIFS(Cant!$I$2:$I$99,Cant!$M$2:$M$99,F12,Cant!$J$2:$J$99,"22/0.5")>0), SUMIFS(Cant!$I$2:$I$99,Cant!$M$2:$M$99,F12,Cant!$J$2:$J$99,"22/0.4") +SUMIFS(Cant!$I$2:$I$99,Cant!$M$2:$M$99,F12,Cant!$J$2:$J$99,"22/0.5"), ""), "") ) | H12: =CONCATENATE(F12) | I12: =IF(AND(F12<>"",COUNTIF($F$11:F11,F12)>0),"",IFERROR( IF(AND(H12<>"", SUMIFS(Cant!$I$2:$I$99,Cant!$M$2:$M$99,H12,Cant!$J$2:$J$99,"22/1.0") +SUMIFS(Cant!$I$2:$I$99,Cant!$M$2:$M$99,H12,Cant!$J$2:$J$99,"23/1.0")>0), SUMIFS(Cant!$I$2:$I$99,Cant!$M$2:$M$99,H12,Cant!$J$2:$J$99,"22/1.0") +SUMIFS(Cant!$I$2:$I$99,Cant!$M$2:$M$99,H12,Cant!$J$2:$J$99,"23/1.0"), ""),"")) | J12: =CONCATENATE(F12) | K12: =IF(AND(F12<>"",COUNTIF($F$11:F11,F12)>0),"",IFERROR(IF(AND(J12<>"",SUMIFS(Cant!$I$2:$I$99,Cant!$M$2:$M$99,J12,Cant!$J$2:$J$99,"23/0.8")>0),SUMIFS(Cant!$I$2:$I$99,Cant!$M$2:$M$99,J12,Cant!$J$2:$J$99,"23/0.8"),""),"")) | L12: =CONCATENATE(F12) | M12: =IF(AND(F12<>"",COUNTIF($F$11:F11,F12)>0),"",IFERROR(IF(AND(L12<>"",SUMIFS(Cant!$I$2:$I$99,Cant!$M$2:$M$99,L12,Cant!$J$2:$J$99,"23/2.0")>0),SUMIFS(Cant!$I$2:$I$99,Cant!$M$2:$M$99,L12,Cant!$J$2:$J$99,"23/2.0"),""),"")) | N12: =CONCATENATE(F12) | O12: =IF(AND(F12<>"",COUNTIF($F$11:F11,F12)>0),"",IFERROR(IF(AND(N12<>"",SUMIFS(Cant!$I$2:$I$99,Cant!$M$2:$M$99,N12,Cant!$J$2:$J$99,"43/1.0")+SUMIFS(Cant!$I$2:$I$99,Cant!$M$2:$M$99,N12,Cant!$J$2:$J$99,"43/0.8")+SUMIFS(Cant!$I$2:$I$99,Cant!$M$2:$M$99,N12,Cant!$J$2:$J$99,"42/1.0")>0),SUMIFS(Cant!$I$2:$I$99,Cant!$M$2:$M$99,N12,Cant!$J$2:$J$99,"43/1.0")+SUMIFS(Cant!$I$2:$I$99,Cant!$M$2:$M$99,N12,Cant!$J$2:$J$99,"43/0.8")+SUMIFS(Cant!$I$2:$I$99,Cant!$M$2:$M$99,N12,Cant!$J$2:$J$99,"42/1.0"),""),"")) | P12: =CONCATENATE(F12) | Q12: =IF(AND(F12<>"",COUNTIF($F$11:F11,F12)>0),"",IFERROR(IF(AND(P12<>"",SUMIFS(Cant!$I$2:$I$99,Cant!$M$2:$M$99,P12,Cant!$J$2:$J$99,"43/1.5")+SUMIFS(Cant!$I$2:$I$99,Cant!$M$2:$M$99,P12,Cant!$J$2:$J$99,"24/1.5")>0),SUMIFS(Cant!$I$2:$I$99,Cant!$M$2:$M$99,P12,Cant!$J$2:$J$99,"43/1.5")+SUMIFS(Cant!$I$2:$I$99,Cant!$M$2:$M$99,P12,Cant!$J$2:$J$99,"24/1.5"),""),"")) | R12: =CONCATENATE(F12) | S12: =IF(AND(F12<>"",COUNTIF($F$11:F11,F12)>0),"",IFERROR(IF(AND(R12<>"",SUMIFS(Cant!$I$2:$I$99,Cant!$M$2:$M$99,R12,Cant!$J$2:$J$99,"43/2.0")>0),SUMIFS(Cant!$I$2:$I$99,Cant!$M$2:$M$99,R12,Cant!$J$2:$J$99,"43/2.0"),""),""))
B13: {=IFERROR(_xlfn.SINGLE(INDEX(Deco!$Y$2:$Y$99,_xlfn.AGGREGATE(15,6,ROW(Deco!$Y$2:$Y$99)-ROW(Deco!$Y$2)+1/(Deco!$W$2:$W$99="PAL"),3))),"")} | C13: {=IFERROR( IF(D13="buc", IF(B13<>"", INDEX(Deco!$C$2:$C$99, MATCH(1, (Deco!$Y$2:$Y$99=B13)*(Deco!$W$2:$W$99="PAL"), 0)), ""), IF(AND(B13<>"", INDEX(Deco!$W$2:$W$99, MATCH(1, (Deco!$Y$2:$Y$99=B13)*(Deco!$W$2:$W$99="PAL"), 0))="PAL"), INDEX(Deco!$V$2:$V$99, MATCH(1, (Deco!$Y$2:$Y$99=B13)*(Deco!$W$2:$W$99="PAL"), 0)), "") ), "")} | D13: {=IF(I3="Debitare căntuire", IF(OR(RIGHT(B13,1)={"0","1","2","3","4","5","6","7","8","9"},RIGHT(B13,2)="SM",RIGHT(B13,2)="PM",RIGHT(B13,2)="PG",RIGHT(B13,2)="mm",RIGHT(B13,2)="mp",RIGHT(B13,2)="PA",RIGHT(B13,2)="3D"),"buc","mp"), "mp")} -> mp | F13: {=IFERROR(INDEX(Cant!$M$2:$M$99,_xlfn.AGGREGATE(15,6,(ROW(Cant!$M$2:$M$99)-ROW(Cant!$M$2)+1)/((Cant!$M$2:$M$99<>"")*(COUNTIF($F$10:F12,Cant!$M$2:$M$99)=0)),1)),"")} | G13: =IF(AND(F13<>"",COUNTIF($F$11:F12,F13)>0),"", IFERROR( IF(AND(F13<>"", SUMIFS(Cant!$I$2:$I$99,Cant!$M$2:$M$99,F13,Cant!$J$2:$J$99,"22/0.4") +SUMIFS(Cant!$I$2:$I$99,Cant!$M$2:$M$99,F13,Cant!$J$2:$J$99,"22/0.5")>0), SUMIFS(Cant!$I$2:$I$99,Cant!$M$2:$M$99,F13,Cant!$J$2:$J$99,"22/0.4") +SUMIFS(Cant!$I$2:$I$99,Cant!$M$2:$M$99,F13,Cant!$J$2:$J$99,"22/0.5"), ""), "") ) | H13: =CONCATENATE(F13) | I13: =IF(AND(F13<>"",COUNTIF($F$11:F12,F13)>0),"",IFERROR( IF(AND(H13<>"", SUMIFS(Cant!$I$2:$I$99,Cant!$M$2:$M$99,H13,Cant!$J$2:$J$99,"22/1.0") +SUMIFS(Cant!$I$2:$I$99,Cant!$M$2:$M$99,H13,Cant!$J$2:$J$99,"23/1.0")>0), SUMIFS(Cant!$I$2:$I$99,Cant!$M$2:$M$99,H13,Cant!$J$2:$J$99,"22/1.0") +SUMIFS(Cant!$I$2:$I$99,Cant!$M$2:$M$99,H13,Cant!$J$2:$J$99,"23/1.0"), ""),"")) | J13: =CONCATENATE(F13) | K13: =IF(AND(F13<>"",COUNTIF($F$11:F12,F13)>0),"",IFERROR(IF(AND(J13<>"",SUMIFS(Cant!$I$2:$I$99,Cant!$M$2:$M$99,J13,Cant!$J$2:$J$99,"23/0.8")>0),SUMIFS(Cant!$I$2:$I$99,Cant!$M$2:$M$99,J13,Cant!$J$2:$J$99,"23/0.8"),""),"")) | L13: =CONCATENATE(F13) | M13: =IF(AND(F13<>"",COUNTIF($F$11:F12,F13)>0),"",IFERROR(IF(AND(L13<>"",SUMIFS(Cant!$I$2:$I$99,Cant!$M$2:$M$99,L13,Cant!$J$2:$J$99,"23/2.0")>0),SUMIFS(Cant!$I$2:$I$99,Cant!$M$2:$M$99,L13,Cant!$J$2:$J$99,"23/2.0"),""),"")) | N13: =CONCATENATE(F13) | O13: =IF(AND(F13<>"",COUNTIF($F$11:F12,F13)>0),"",IFERROR(IF(AND(N13<>"",SUMIFS(Cant!$I$2:$I$99,Cant!$M$2:$M$99,N13,Cant!$J$2:$J$99,"43/1.0")+SUMIFS(Cant!$I$2:$I$99,Cant!$M$2:$M$99,N13,Cant!$J$2:$J$99,"43/0.8")+SUMIFS(Cant!$I$2:$I$99,Cant!$M$2:$M$99,N13,Cant!$J$2:$J$99,"42/1.0")>0),SUMIFS(Cant!$I$2:$I$99,Cant!$M$2:$M$99,N13,Cant!$J$2:$J$99,"43/1.0")+SUMIFS(Cant!$I$2:$I$99,Cant!$M$2:$M$99,N13,Cant!$J$2:$J$99,"43/0.8")+SUMIFS(Cant!$I$2:$I$99,Cant!$M$2:$M$99,N13,Cant!$J$2:$J$99,"42/1.0"),""),"")) | P13: =CONCATENATE(F13) | Q13: =IF(AND(F13<>"",COUNTIF($F$11:F12,F13)>0),"",IFERROR(IF(AND(P13<>"",SUMIFS(Cant!$I$2:$I$99,Cant!$M$2:$M$99,P13,Cant!$J$2:$J$99,"43/1.5")+SUMIFS(Cant!$I$2:$I$99,Cant!$M$2:$M$99,P13,Cant!$J$2:$J$99,"24/1.5")>0),SUMIFS(Cant!$I$2:$I$99,Cant!$M$2:$M$99,P13,Cant!$J$2:$J$99,"43/1.5")+SUMIFS(Cant!$I$2:$I$99,Cant!$M$2:$M$99,P13,Cant!$J$2:$J$99,"24/1.5"),""),"")) | R13: =CONCATENATE(F13) | S13: =IF(AND(F13<>"",COUNTIF($F$11:F12,F13)>0),"",IFERROR(IF(AND(R13<>"",SUMIFS(Cant!$I$2:$I$99,Cant!$M$2:$M$99,R13,Cant!$J$2:$J$99,"43/2.0")>0),SUMIFS(Cant!$I$2:$I$99,Cant!$M$2:$M$99,R13,Cant!$J$2:$J$99,"43/2.0"),""),""))
B14: {=IFERROR(_xlfn.SINGLE(INDEX(Deco!$Y$2:$Y$99,_xlfn.AGGREGATE(15,6,ROW(Deco!$Y$2:$Y$99)-ROW(Deco!$Y$2)+1/(Deco!$W$2:$W$99="PAL"),4))),"")} | C14: {=IFERROR( IF(D14="buc", IF(B14<>"", INDEX(Deco!$C$2:$C$99, MATCH(1, (Deco!$Y$2:$Y$99=B14)*(Deco!$W$2:$W$99="PAL"), 0)), ""), IF(AND(B14<>"", INDEX(Deco!$W$2:$W$99, MATCH(1, (Deco!$Y$2:$Y$99=B14)*(Deco!$W$2:$W$99="PAL"), 0))="PAL"), INDEX(Deco!$V$2:$V$99, MATCH(1, (Deco!$Y$2:$Y$99=B14)*(Deco!$W$2:$W$99="PAL"), 0)), "") ), "")} | D14: {=IF(I3="Debitare căntuire", IF(OR(RIGHT(B14,1)={"0","1","2","3","4","5","6","7","8","9"},RIGHT(B14,2)="SM",RIGHT(B14,2)="PM",RIGHT(B14,2)="PG",RIGHT(B14,2)="mm",RIGHT(B14,2)="mp",RIGHT(B14,2)="PA",RIGHT(B14,2)="3D"),"buc","mp"), "mp")} -> mp | F14: {=IFERROR(INDEX(Cant!$M$2:$M$99,_xlfn.AGGREGATE(15,6,(ROW(Cant!$M$2:$M$99)-ROW(Cant!$M$2)+1)/((Cant!$M$2:$M$99<>"")*(COUNTIF($F$10:F13,Cant!$M$2:$M$99)=0)),1)),"")} | G14: =IF(AND(F14<>"",COUNTIF($F$11:F13,F14)>0),"", IFERROR( IF(AND(F14<>"", SUMIFS(Cant!$I$2:$I$99,Cant!$M$2:$M$99,F14,Cant!$J$2:$J$99,"22/0.4") +SUMIFS(Cant!$I$2:$I$99,Cant!$M$2:$M$99,F14,Cant!$J$2:$J$99,"22/0.5")>0), SUMIFS(Cant!$I$2:$I$99,Cant!$M$2:$M$99,F14,Cant!$J$2:$J$99,"22/0.4") +SUMIFS(Cant!$I$2:$I$99,Cant!$M$2:$M$99,F14,Cant!$J$2:$J$99,"22/0.5"), ""), "") ) | H14: =CONCATENATE(F14) | I14: =IF(AND(F14<>"",COUNTIF($F$11:F13,F14)>0),"",IFERROR( IF(AND(H14<>"", SUMIFS(Cant!$I$2:$I$99,Cant!$M$2:$M$99,H14,Cant!$J$2:$J$99,"22/1.0") +SUMIFS(Cant!$I$2:$I$99,Cant!$M$2:$M$99,H14,Cant!$J$2:$J$99,"23/1.0")>0), SUMIFS(Cant!$I$2:$I$99,Cant!$M$2:$M$99,H14,Cant!$J$2:$J$99,"22/1.0") +SUMIFS(Cant!$I$2:$I$99,Cant!$M$2:$M$99,H14,Cant!$J$2:$J$99,"23/1.0"), ""),"")) | J14: =CONCATENATE(F14) | K14: =IF(AND(F14<>"",COUNTIF($F$11:F13,F14)>0),"",IFERROR(IF(AND(J14<>"",SUMIFS(Cant!$I$2:$I$99,Cant!$M$2:$M$99,J14,Cant!$J$2:$J$99,"23/0.8")>0),SUMIFS(Cant!$I$2:$I$99,Cant!$M$2:$M$99,J14,Cant!$J$2:$J$99,"23/0.8"),""),"")) | L14: =CONCATENATE(F14) | M14: =IF(AND(F14<>"",COUNTIF($F$11:F13,F14)>0),"",IFERROR(IF(AND(L14<>"",SUMIFS(Cant!$I$2:$I$99,Cant!$M$2:$M$99,L14,Cant!$J$2:$J$99,"23/2.0")>0),SUMIFS(Cant!$I$2:$I$99,Cant!$M$2:$M$99,L14,Cant!$J$2:$J$99,"23/2.0"),""),"")) | N14: =CONCATENATE(F14) | O14: =IF(AND(F14<>"",COUNTIF($F$11:F13,F14)>0),"",IFERROR(IF(AND(N14<>"",SUMIFS(Cant!$I$2:$I$99,Cant!$M$2:$M$99,N14,Cant!$J$2:$J$99,"43/1.0")+SUMIFS(Cant!$I$2:$I$99,Cant!$M$2:$M$99,N14,Cant!$J$2:$J$99,"43/0.8")+SUMIFS(Cant!$I$2:$I$99,Cant!$M$2:$M$99,N14,Cant!$J$2:$J$99,"42/1.0")>0),SUMIFS(Cant!$I$2:$I$99,Cant!$M$2:$M$99,N14,Cant!$J$2:$J$99,"43/1.0")+SUMIFS(Cant!$I$2:$I$99,Cant!$M$2:$M$99,N14,Cant!$J$2:$J$99,"43/0.8")+SUMIFS(Cant!$I$2:$I$99,Cant!$M$2:$M$99,N14,Cant!$J$2:$J$99,"42/1.0"),""),"")) | P14: =CONCATENATE(F14) | Q14: =IF(AND(F14<>"",COUNTIF($F$11:F13,F14)>0),"",IFERROR(IF(AND(P14<>"",SUMIFS(Cant!$I$2:$I$99,Cant!$M$2:$M$99,P14,Cant!$J$2:$J$99,"43/1.5")+SUMIFS(Cant!$I$2:$I$99,Cant!$M$2:$M$99,P14,Cant!$J$2:$J$99,"24/1.5")>0),SUMIFS(Cant!$I$2:$I$99,Cant!$M$2:$M$99,P14,Cant!$J$2:$J$99,"43/1.5")+SUMIFS(Cant!$I$2:$I$99,Cant!$M$2:$M$99,P14,Cant!$J$2:$J$99,"24/1.5"),""),"")) | R14: =CONCATENATE(F14) | S14: =IF(AND(F14<>"",COUNTIF($F$11:F13,F14)>0),"",IFERROR(IF(AND(R14<>"",SUMIFS(Cant!$I$2:$I$99,Cant!$M$2:$M$99,R14,Cant!$J$2:$J$99,"43/2.0")>0),SUMIFS(Cant!$I$2:$I$99,Cant!$M$2:$M$99,R14,Cant!$J$2:$J$99,"43/2.0"),""),""))
B15: {=IFERROR(_xlfn.SINGLE(INDEX(Deco!$Y$2:$Y$99,_xlfn.AGGREGATE(15,6,ROW(Deco!$Y$2:$Y$99)-ROW(Deco!$Y$2)+1/(Deco!$W$2:$W$99="PAL"),5))),"")} | C15: {=IFERROR( IF(D15="buc", IF(B15<>"", INDEX(Deco!$C$2:$C$99, MATCH(1, (Deco!$Y$2:$Y$99=B15)*(Deco!$W$2:$W$99="PAL"), 0)), ""), IF(AND(B15<>"", INDEX(Deco!$W$2:$W$99, MATCH(1, (Deco!$Y$2:$Y$99=B15)*(Deco!$W$2:$W$99="PAL"), 0))="PAL"), INDEX(Deco!$V$2:$V$99, MATCH(1, (Deco!$Y$2:$Y$99=B15)*(Deco!$W$2:$W$99="PAL"), 0)), "") ), "")} | D15: {=IF(I3="Debitare căntuire", IF(OR(RIGHT(B15,1)={"0","1","2","3","4","5","6","7","8","9"},RIGHT(B15,2)="SM",RIGHT(B15,2)="PM",RIGHT(B15,2)="PG",RIGHT(B15,2)="mm",RIGHT(B15,2)="mp",RIGHT(B15,2)="PA",RIGHT(B15,2)="3D"),"buc","mp"), "mp")} -> mp | F15: {=IFERROR(INDEX(Cant!$M$2:$M$99,_xlfn.AGGREGATE(15,6,(ROW(Cant!$M$2:$M$99)-ROW(Cant!$M$2)+1)/((Cant!$M$2:$M$99<>"")*(COUNTIF($F$10:F14,Cant!$M$2:$M$99)=0)),1)),"")} | G15: =IF(AND(F15<>"",COUNTIF($F$11:F14,F15)>0),"", IFERROR( IF(AND(F15<>"", SUMIFS(Cant!$I$2:$I$99,Cant!$M$2:$M$99,F15,Cant!$J$2:$J$99,"22/0.4") +SUMIFS(Cant!$I$2:$I$99,Cant!$M$2:$M$99,F15,Cant!$J$2:$J$99,"22/0.5")>0), SUMIFS(Cant!$I$2:$I$99,Cant!$M$2:$M$99,F15,Cant!$J$2:$J$99,"22/0.4") +SUMIFS(Cant!$I$2:$I$99,Cant!$M$2:$M$99,F15,Cant!$J$2:$J$99,"22/0.5"), ""), "") ) | H15: =CONCATENATE(F15) | I15: =IF(AND(F15<>"",COUNTIF($F$11:F14,F15)>0),"",IFERROR( IF(AND(H15<>"", SUMIFS(Cant!$I$2:$I$99,Cant!$M$2:$M$99,H15,Cant!$J$2:$J$99,"22/1.0") +SUMIFS(Cant!$I$2:$I$99,Cant!$M$2:$M$99,H15,Cant!$J$2:$J$99,"23/1.0")>0), SUMIFS(Cant!$I$2:$I$99,Cant!$M$2:$M$99,H15,Cant!$J$2:$J$99,"22/1.0") +SUMIFS(Cant!$I$2:$I$99,Cant!$M$2:$M$99,H15,Cant!$J$2:$J$99,"23/1.0"), ""),"")) | J15: =CONCATENATE(F15) | K15: =IF(AND(F15<>"",COUNTIF($F$11:F14,F15)>0),"",IFERROR(IF(AND(J15<>"",SUMIFS(Cant!$I$2:$I$99,Cant!$M$2:$M$99,J15,Cant!$J$2:$J$99,"23/0.8")>0),SUMIFS(Cant!$I$2:$I$99,Cant!$M$2:$M$99,J15,Cant!$J$2:$J$99,"23/0.8"),""),"")) | L15: =CONCATENATE(F15) | M15: =IF(AND(F15<>"",COUNTIF($F$11:F14,F15)>0),"",IFERROR(IF(AND(L15<>"",SUMIFS(Cant!$I$2:$I$99,Cant!$M$2:$M$99,L15,Cant!$J$2:$J$99,"23/2.0")>0),SUMIFS(Cant!$I$2:$I$99,Cant!$M$2:$M$99,L15,Cant!$J$2:$J$99,"23/2.0"),""),"")) | N15: =CONCATENATE(F15) | O15: =IF(AND(F15<>"",COUNTIF($F$11:F14,F15)>0),"",IFERROR(IF(AND(N15<>"",SUMIFS(Cant!$I$2:$I$99,Cant!$M$2:$M$99,N15,Cant!$J$2:$J$99,"43/1.0")+SUMIFS(Cant!$I$2:$I$99,Cant!$M$2:$M$99,N15,Cant!$J$2:$J$99,"43/0.8")+SUMIFS(Cant!$I$2:$I$99,Cant!$M$2:$M$99,N15,Cant!$J$2:$J$99,"42/1.0")>0),SUMIFS(Cant!$I$2:$I$99,Cant!$M$2:$M$99,N15,Cant!$J$2:$J$99,"43/1.0")+SUMIFS(Cant!$I$2:$I$99,Cant!$M$2:$M$99,N15,Cant!$J$2:$J$99,"43/0.8")+SUMIFS(Cant!$I$2:$I$99,Cant!$M$2:$M$99,N15,Cant!$J$2:$J$99,"42/1.0"),""),"")) | P15: =CONCATENATE(F15) | Q15: =IF(AND(F15<>"",COUNTIF($F$11:F14,F15)>0),"",IFERROR(IF(AND(P15<>"",SUMIFS(Cant!$I$2:$I$99,Cant!$M$2:$M$99,P15,Cant!$J$2:$J$99,"43/1.5")+SUMIFS(Cant!$I$2:$I$99,Cant!$M$2:$M$99,P15,Cant!$J$2:$J$99,"24/1.5")>0),SUMIFS(Cant!$I$2:$I$99,Cant!$M$2:$M$99,P15,Cant!$J$2:$J$99,"43/1.5")+SUMIFS(Cant!$I$2:$I$99,Cant!$M$2:$M$99,P15,Cant!$J$2:$J$99,"24/1.5"),""),"")) | R15: =CONCATENATE(F15) | S15: =IF(AND(F15<>"",COUNTIF($F$11:F14,F15)>0),"",IFERROR(IF(AND(R15<>"",SUMIFS(Cant!$I$2:$I$99,Cant!$M$2:$M$99,R15,Cant!$J$2:$J$99,"43/2.0")>0),SUMIFS(Cant!$I$2:$I$99,Cant!$M$2:$M$99,R15,Cant!$J$2:$J$99,"43/2.0"),""),""))
B16: {=IFERROR(_xlfn.SINGLE(INDEX(Deco!$Y$2:$Y$99,_xlfn.AGGREGATE(15,6,ROW(Deco!$Y$2:$Y$99)-ROW(Deco!$Y$2)+1/(Deco!$W$2:$W$99="PAL"),6))),"")} | C16: {=IFERROR( IF(D16="buc", IF(B16<>"", INDEX(Deco!$C$2:$C$99, MATCH(1, (Deco!$Y$2:$Y$99=B16)*(Deco!$W$2:$W$99="PAL"), 0)), ""), IF(AND(B16<>"", INDEX(Deco!$W$2:$W$99, MATCH(1, (Deco!$Y$2:$Y$99=B16)*(Deco!$W$2:$W$99="PAL"), 0))="PAL"), INDEX(Deco!$V$2:$V$99, MATCH(1, (Deco!$Y$2:$Y$99=B16)*(Deco!$W$2:$W$99="PAL"), 0)), "") ), "")} | D16: {=IF(I3="Debitare căntuire", IF(OR(RIGHT(B16,1)={"0","1","2","3","4","5","6","7","8","9"},RIGHT(B16,2)="SM",RIGHT(B16,2)="PM",RIGHT(B16,2)="PG",RIGHT(B16,2)="mm",RIGHT(B16,2)="mp",RIGHT(B16,2)="PA",RIGHT(B16,2)="3D"),"buc","mp"), "mp")} -> mp | F16: {=IFERROR(INDEX(Cant!$M$2:$M$99,_xlfn.AGGREGATE(15,6,(ROW(Cant!$M$2:$M$99)-ROW(Cant!$M$2)+1)/((Cant!$M$2:$M$99<>"")*(COUNTIF($F$10:F15,Cant!$M$2:$M$99)=0)),1)),"")} | G16: =IF(AND(F16<>"",COUNTIF($F$11:F15,F16)>0),"", IFERROR( IF(AND(F16<>"", SUMIFS(Cant!$I$2:$I$99,Cant!$M$2:$M$99,F16,Cant!$J$2:$J$99,"22/0.4") +SUMIFS(Cant!$I$2:$I$99,Cant!$M$2:$M$99,F16,Cant!$J$2:$J$99,"22/0.5")>0), SUMIFS(Cant!$I$2:$I$99,Cant!$M$2:$M$99,F16,Cant!$J$2:$J$99,"22/0.4") +SUMIFS(Cant!$I$2:$I$99,Cant!$M$2:$M$99,F16,Cant!$J$2:$J$99,"22/0.5"), ""), "") ) | H16: =CONCATENATE(F16) | I16: =IF(AND(F16<>"",COUNTIF($F$11:F15,F16)>0),"",IFERROR( IF(AND(H16<>"", SUMIFS(Cant!$I$2:$I$99,Cant!$M$2:$M$99,H16,Cant!$J$2:$J$99,"22/1.0") +SUMIFS(Cant!$I$2:$I$99,Cant!$M$2:$M$99,H16,Cant!$J$2:$J$99,"23/1.0")>0), SUMIFS(Cant!$I$2:$I$99,Cant!$M$2:$M$99,H16,Cant!$J$2:$J$99,"22/1.0") +SUMIFS(Cant!$I$2:$I$99,Cant!$M$2:$M$99,H16,Cant!$J$2:$J$99,"23/1.0"), ""),"")) | J16: =CONCATENATE(F16) | K16: =IF(AND(F16<>"",COUNTIF($F$11:F15,F16)>0),"",IFERROR(IF(AND(J16<>"",SUMIFS(Cant!$I$2:$I$99,Cant!$M$2:$M$99,J16,Cant!$J$2:$J$99,"23/0.8")>0),SUMIFS(Cant!$I$2:$I$99,Cant!$M$2:$M$99,J16,Cant!$J$2:$J$99,"23/0.8"),""),"")) | L16: =CONCATENATE(F16) | M16: =IF(AND(F16<>"",COUNTIF($F$11:F15,F16)>0),"",IFERROR(IF(AND(L16<>"",SUMIFS(Cant!$I$2:$I$99,Cant!$M$2:$M$99,L16,Cant!$J$2:$J$99,"23/2.0")>0),SUMIFS(Cant!$I$2:$I$99,Cant!$M$2:$M$99,L16,Cant!$J$2:$J$99,"23/2.0"),""),"")) | N16: =CONCATENATE(F16) | O16: =IF(AND(F16<>"",COUNTIF($F$11:F15,F16)>0),"",IFERROR(IF(AND(N16<>"",SUMIFS(Cant!$I$2:$I$99,Cant!$M$2:$M$99,N16,Cant!$J$2:$J$99,"43/1.0")+SUMIFS(Cant!$I$2:$I$99,Cant!$M$2:$M$99,N16,Cant!$J$2:$J$99,"43/0.8")+SUMIFS(Cant!$I$2:$I$99,Cant!$M$2:$M$99,N16,Cant!$J$2:$J$99,"42/1.0")>0),SUMIFS(Cant!$I$2:$I$99,Cant!$M$2:$M$99,N16,Cant!$J$2:$J$99,"43/1.0")+SUMIFS(Cant!$I$2:$I$99,Cant!$M$2:$M$99,N16,Cant!$J$2:$J$99,"43/0.8")+SUMIFS(Cant!$I$2:$I$99,Cant!$M$2:$M$99,N16,Cant!$J$2:$J$99,"42/1.0"),""),"")) | P16: =CONCATENATE(F16) | Q16: =IF(AND(F16<>"",COUNTIF($F$11:F15,F16)>0),"",IFERROR(IF(AND(P16<>"",SUMIFS(Cant!$I$2:$I$99,Cant!$M$2:$M$99,P16,Cant!$J$2:$J$99,"43/1.5")+SUMIFS(Cant!$I$2:$I$99,Cant!$M$2:$M$99,P16,Cant!$J$2:$J$99,"24/1.5")>0),SUMIFS(Cant!$I$2:$I$99,Cant!$M$2:$M$99,P16,Cant!$J$2:$J$99,"43/1.5")+SUMIFS(Cant!$I$2:$I$99,Cant!$M$2:$M$99,P16,Cant!$J$2:$J$99,"24/1.5"),""),"")) | R16: =CONCATENATE(F16) | S16: =IF(AND(F16<>"",COUNTIF($F$11:F15,F16)>0),"",IFERROR(IF(AND(R16<>"",SUMIFS(Cant!$I$2:$I$99,Cant!$M$2:$M$99,R16,Cant!$J$2:$J$99,"43/2.0")>0),SUMIFS(Cant!$I$2:$I$99,Cant!$M$2:$M$99,R16,Cant!$J$2:$J$99,"43/2.0"),""),""))
B17: {=IFERROR(_xlfn.SINGLE(INDEX(Deco!$Y$2:$Y$99,_xlfn.AGGREGATE(15,6,ROW(Deco!$Y$2:$Y$99)-ROW(Deco!$Y$2)+1/(Deco!$W$2:$W$99="PAL"),7))),"")} | C17: {=IFERROR( IF(D17="buc", IF(B17<>"", INDEX(Deco!$C$2:$C$99, MATCH(1, (Deco!$Y$2:$Y$99=B17)*(Deco!$W$2:$W$99="PAL"), 0)), ""), IF(AND(B17<>"", INDEX(Deco!$W$2:$W$99, MATCH(1, (Deco!$Y$2:$Y$99=B17)*(Deco!$W$2:$W$99="PAL"), 0))="PAL"), INDEX(Deco!$V$2:$V$99, MATCH(1, (Deco!$Y$2:$Y$99=B17)*(Deco!$W$2:$W$99="PAL"), 0)), "") ), "")} | D17: {=IF(I3="Debitare căntuire", IF(OR(RIGHT(B17,1)={"0","1","2","3","4","5","6","7","8","9"},RIGHT(B17,2)="SM",RIGHT(B17,2)="PM",RIGHT(B17,2)="PG",RIGHT(B17,2)="mm",RIGHT(B17,2)="mp",RIGHT(B17,2)="PA",RIGHT(B17,2)="3D"),"buc","mp"), "mp")} -> mp | F17: {=IFERROR(INDEX(Cant!$M$2:$M$99,_xlfn.AGGREGATE(15,6,(ROW(Cant!$M$2:$M$99)-ROW(Cant!$M$2)+1)/((Cant!$M$2:$M$99<>"")*(COUNTIF($F$10:F16,Cant!$M$2:$M$99)=0)),1)),"")} | G17: =IF(AND(F17<>"",COUNTIF($F$11:F16,F17)>0),"", IFERROR( IF(AND(F17<>"", SUMIFS(Cant!$I$2:$I$99,Cant!$M$2:$M$99,F17,Cant!$J$2:$J$99,"22/0.4") +SUMIFS(Cant!$I$2:$I$99,Cant!$M$2:$M$99,F17,Cant!$J$2:$J$99,"22/0.5")>0), SUMIFS(Cant!$I$2:$I$99,Cant!$M$2:$M$99,F17,Cant!$J$2:$J$99,"22/0.4") +SUMIFS(Cant!$I$2:$I$99,Cant!$M$2:$M$99,F17,Cant!$J$2:$J$99,"22/0.5"), ""), "") ) | H17: =CONCATENATE(F17) | I17: =IF(AND(F17<>"",COUNTIF($F$11:F16,F17)>0),"",IFERROR( IF(AND(H17<>"", SUMIFS(Cant!$I$2:$I$99,Cant!$M$2:$M$99,H17,Cant!$J$2:$J$99,"22/1.0") +SUMIFS(Cant!$I$2:$I$99,Cant!$M$2:$M$99,H17,Cant!$J$2:$J$99,"23/1.0")>0), SUMIFS(Cant!$I$2:$I$99,Cant!$M$2:$M$99,H17,Cant!$J$2:$J$99,"22/1.0") +SUMIFS(Cant!$I$2:$I$99,Cant!$M$2:$M$99,H17,Cant!$J$2:$J$99,"23/1.0"), ""),"")) | J17: =CONCATENATE(F17) | K17: =IF(AND(F17<>"",COUNTIF($F$11:F16,F17)>0),"",IFERROR(IF(AND(J17<>"",SUMIFS(Cant!$I$2:$I$99,Cant!$M$2:$M$99,J17,Cant!$J$2:$J$99,"23/0.8")>0),SUMIFS(Cant!$I$2:$I$99,Cant!$M$2:$M$99,J17,Cant!$J$2:$J$99,"23/0.8"),""),"")) | L17: =CONCATENATE(F17) | M17: =IF(AND(F17<>"",COUNTIF($F$11:F16,F17)>0),"",IFERROR(IF(AND(L17<>"",SUMIFS(Cant!$I$2:$I$99,Cant!$M$2:$M$99,L17,Cant!$J$2:$J$99,"23/2.0")>0),SUMIFS(Cant!$I$2:$I$99,Cant!$M$2:$M$99,L17,Cant!$J$2:$J$99,"23/2.0"),""),"")) | N17: =CONCATENATE(F17) | O17: =IF(AND(F17<>"",COUNTIF($F$11:F16,F17)>0),"",IFERROR(IF(AND(N17<>"",SUMIFS(Cant!$I$2:$I$99,Cant!$M$2:$M$99,N17,Cant!$J$2:$J$99,"43/1.0")+SUMIFS(Cant!$I$2:$I$99,Cant!$M$2:$M$99,N17,Cant!$J$2:$J$99,"43/0.8")+SUMIFS(Cant!$I$2:$I$99,Cant!$M$2:$M$99,N17,Cant!$J$2:$J$99,"42/1.0")>0),SUMIFS(Cant!$I$2:$I$99,Cant!$M$2:$M$99,N17,Cant!$J$2:$J$99,"43/1.0")+SUMIFS(Cant!$I$2:$I$99,Cant!$M$2:$M$99,N17,Cant!$J$2:$J$99,"43/0.8")+SUMIFS(Cant!$I$2:$I$99,Cant!$M$2:$M$99,N17,Cant!$J$2:$J$99,"42/1.0"),""),"")) | P17: =CONCATENATE(F17) | Q17: =IF(AND(F17<>"",COUNTIF($F$11:F16,F17)>0),"",IFERROR(IF(AND(P17<>"",SUMIFS(Cant!$I$2:$I$99,Cant!$M$2:$M$99,P17,Cant!$J$2:$J$99,"43/1.5")+SUMIFS(Cant!$I$2:$I$99,Cant!$M$2:$M$99,P17,Cant!$J$2:$J$99,"24/1.5")>0),SUMIFS(Cant!$I$2:$I$99,Cant!$M$2:$M$99,P17,Cant!$J$2:$J$99,"43/1.5")+SUMIFS(Cant!$I$2:$I$99,Cant!$M$2:$M$99,P17,Cant!$J$2:$J$99,"24/1.5"),""),"")) | R17: =CONCATENATE(F17) | S17: =IF(AND(F17<>"",COUNTIF($F$11:F16,F17)>0),"",IFERROR(IF(AND(R17<>"",SUMIFS(Cant!$I$2:$I$99,Cant!$M$2:$M$99,R17,Cant!$J$2:$J$99,"43/2.0")>0),SUMIFS(Cant!$I$2:$I$99,Cant!$M$2:$M$99,R17,Cant!$J$2:$J$99,"43/2.0"),""),""))
B18: {=IFERROR(_xlfn.SINGLE(INDEX(Deco!$Y$2:$Y$99,_xlfn.AGGREGATE(15,6,ROW(Deco!$Y$2:$Y$99)-ROW(Deco!$Y$2)+1/(Deco!$W$2:$W$99="PAL"),8))),"")} | C18: {=IFERROR( IF(D18="buc", IF(B18<>"", INDEX(Deco!$C$2:$C$99, MATCH(1, (Deco!$Y$2:$Y$99=B18)*(Deco!$W$2:$W$99="PAL"), 0)), ""), IF(AND(B18<>"", INDEX(Deco!$W$2:$W$99, MATCH(1, (Deco!$Y$2:$Y$99=B18)*(Deco!$W$2:$W$99="PAL"), 0))="PAL"), INDEX(Deco!$V$2:$V$99, MATCH(1, (Deco!$Y$2:$Y$99=B18)*(Deco!$W$2:$W$99="PAL"), 0)), "") ), "")} | D18: {=IF(I3="Debitare căntuire", IF(OR(RIGHT(B18,1)={"0","1","2","3","4","5","6","7","8","9"},RIGHT(B18,2)="SM",RIGHT(B18,2)="PM",RIGHT(B18,2)="PG",RIGHT(B18,2)="mm",RIGHT(B18,2)="mp",RIGHT(B18,2)="PA",RIGHT(B18,2)="3D"),"buc","mp"), "mp")} -> mp | F18: {=IFERROR(INDEX(Cant!$M$2:$M$99,_xlfn.AGGREGATE(15,6,(ROW(Cant!$M$2:$M$99)-ROW(Cant!$M$2)+1)/((Cant!$M$2:$M$99<>"")*(COUNTIF($F$10:F17,Cant!$M$2:$M$99)=0)),1)),"")} | G18: =IF(AND(F18<>"",COUNTIF($F$11:F17,F18)>0),"", IFERROR( IF(AND(F18<>"", SUMIFS(Cant!$I$2:$I$99,Cant!$M$2:$M$99,F18,Cant!$J$2:$J$99,"22/0.4") +SUMIFS(Cant!$I$2:$I$99,Cant!$M$2:$M$99,F18,Cant!$J$2:$J$99,"22/0.5")>0), SUMIFS(Cant!$I$2:$I$99,Cant!$M$2:$M$99,F18,Cant!$J$2:$J$99,"22/0.4") +SUMIFS(Cant!$I$2:$I$99,Cant!$M$2:$M$99,F18,Cant!$J$2:$J$99,"22/0.5"), ""), "") ) | H18: =CONCATENATE(F18) | I18: =IF(AND(F18<>"",COUNTIF($F$11:F17,F18)>0),"",IFERROR( IF(AND(H18<>"", SUMIFS(Cant!$I$2:$I$99,Cant!$M$2:$M$99,H18,Cant!$J$2:$J$99,"22/1.0") +SUMIFS(Cant!$I$2:$I$99,Cant!$M$2:$M$99,H18,Cant!$J$2:$J$99,"23/1.0")>0), SUMIFS(Cant!$I$2:$I$99,Cant!$M$2:$M$99,H18,Cant!$J$2:$J$99,"22/1.0") +SUMIFS(Cant!$I$2:$I$99,Cant!$M$2:$M$99,H18,Cant!$J$2:$J$99,"23/1.0"), ""),"")) | J18: =CONCATENATE(F18) | K18: =IF(AND(F18<>"",COUNTIF($F$11:F17,F18)>0),"",IFERROR(IF(AND(J18<>"",SUMIFS(Cant!$I$2:$I$99,Cant!$M$2:$M$99,J18,Cant!$J$2:$J$99,"23/0.8")>0),SUMIFS(Cant!$I$2:$I$99,Cant!$M$2:$M$99,J18,Cant!$J$2:$J$99,"23/0.8"),""),"")) | L18: =CONCATENATE(F18) | M18: =IF(AND(F18<>"",COUNTIF($F$11:F17,F18)>0),"",IFERROR(IF(AND(L18<>"",SUMIFS(Cant!$I$2:$I$99,Cant!$M$2:$M$99,L18,Cant!$J$2:$J$99,"23/2.0")>0),SUMIFS(Cant!$I$2:$I$99,Cant!$M$2:$M$99,L18,Cant!$J$2:$J$99,"23/2.0"),""),"")) | N18: =CONCATENATE(F18) | O18: =IF(AND(F18<>"",COUNTIF($F$11:F17,F18)>0),"",IFERROR(IF(AND(N18<>"",SUMIFS(Cant!$I$2:$I$99,Cant!$M$2:$M$99,N18,Cant!$J$2:$J$99,"43/1.0")+SUMIFS(Cant!$I$2:$I$99,Cant!$M$2:$M$99,N18,Cant!$J$2:$J$99,"43/0.8")+SUMIFS(Cant!$I$2:$I$99,Cant!$M$2:$M$99,N18,Cant!$J$2:$J$99,"42/1.0")>0),SUMIFS(Cant!$I$2:$I$99,Cant!$M$2:$M$99,N18,Cant!$J$2:$J$99,"43/1.0")+SUMIFS(Cant!$I$2:$I$99,Cant!$M$2:$M$99,N18,Cant!$J$2:$J$99,"43/0.8")+SUMIFS(Cant!$I$2:$I$99,Cant!$M$2:$M$99,N18,Cant!$J$2:$J$99,"42/1.0"),""),"")) | P18: =CONCATENATE(F18) | Q18: =IF(AND(F18<>"",COUNTIF($F$11:F17,F18)>0),"",IFERROR(IF(AND(P18<>"",SUMIFS(Cant!$I$2:$I$99,Cant!$M$2:$M$99,P18,Cant!$J$2:$J$99,"43/1.5")+SUMIFS(Cant!$I$2:$I$99,Cant!$M$2:$M$99,P18,Cant!$J$2:$J$99,"24/1.5")>0),SUMIFS(Cant!$I$2:$I$99,Cant!$M$2:$M$99,P18,Cant!$J$2:$J$99,"43/1.5")+SUMIFS(Cant!$I$2:$I$99,Cant!$M$2:$M$99,P18,Cant!$J$2:$J$99,"24/1.5"),""),"")) | R18: =CONCATENATE(F18) | S18: =IF(AND(F18<>"",COUNTIF($F$11:F17,F18)>0),"",IFERROR(IF(AND(R18<>"",SUMIFS(Cant!$I$2:$I$99,Cant!$M$2:$M$99,R18,Cant!$J$2:$J$99,"43/2.0")>0),SUMIFS(Cant!$I$2:$I$99,Cant!$M$2:$M$99,R18,Cant!$J$2:$J$99,"43/2.0"),""),""))
B19: {=IFERROR(_xlfn.SINGLE(INDEX(Deco!$Y$2:$Y$99,_xlfn.AGGREGATE(15,6,ROW(Deco!$Y$2:$Y$99)-ROW(Deco!$Y$2)+1/(Deco!$W$2:$W$99="PAL"),9))),"")} | C19: {=IFERROR( IF(D19="buc", IF(B19<>"", INDEX(Deco!$C$2:$C$99, MATCH(1, (Deco!$Y$2:$Y$99=B19)*(Deco!$W$2:$W$99="PAL"), 0)), ""), IF(AND(B19<>"", INDEX(Deco!$W$2:$W$99, MATCH(1, (Deco!$Y$2:$Y$99=B19)*(Deco!$W$2:$W$99="PAL"), 0))="PAL"), INDEX(Deco!$V$2:$V$99, MATCH(1, (Deco!$Y$2:$Y$99=B19)*(Deco!$W$2:$W$99="PAL"), 0)), "") ), "")} | D19: {=IF(I3="Debitare căntuire", IF(OR(RIGHT(B19,1)={"0","1","2","3","4","5","6","7","8","9"},RIGHT(B19,2)="SM",RIGHT(B19,2)="PM",RIGHT(B19,2)="PG",RIGHT(B19,2)="mm",RIGHT(B19,2)="mp",,RIGHT(B19,2)="PA",RIGHT(B19,2)="3D"),"buc","mp"), "mp")} -> mp | F19: {=IFERROR(INDEX(Cant!$M$2:$M$99,_xlfn.AGGREGATE(15,6,(ROW(Cant!$M$2:$M$99)-ROW(Cant!$M$2)+1)/((Cant!$M$2:$M$99<>"")*(COUNTIF($F$10:F18,Cant!$M$2:$M$99)=0)),1)),"")} | G19: =IF(AND(F19<>"",COUNTIF($F$11:F18,F19)>0),"", IFERROR( IF(AND(F19<>"", SUMIFS(Cant!$I$2:$I$99,Cant!$M$2:$M$99,F19,Cant!$J$2:$J$99,"22/0.4") +SUMIFS(Cant!$I$2:$I$99,Cant!$M$2:$M$99,F19,Cant!$J$2:$J$99,"22/0.5")>0), SUMIFS(Cant!$I$2:$I$99,Cant!$M$2:$M$99,F19,Cant!$J$2:$J$99,"22/0.4") +SUMIFS(Cant!$I$2:$I$99,Cant!$M$2:$M$99,F19,Cant!$J$2:$J$99,"22/0.5"), ""), "") ) | H19: =CONCATENATE(F19) | I19: =IF(AND(F19<>"",COUNTIF($F$11:F18,F19)>0),"",IFERROR( IF(AND(H19<>"", SUMIFS(Cant!$I$2:$I$99,Cant!$M$2:$M$99,H19,Cant!$J$2:$J$99,"22/1.0") +SUMIFS(Cant!$I$2:$I$99,Cant!$M$2:$M$99,H19,Cant!$J$2:$J$99,"23/1.0")>0), SUMIFS(Cant!$I$2:$I$99,Cant!$M$2:$M$99,H19,Cant!$J$2:$J$99,"22/1.0") +SUMIFS(Cant!$I$2:$I$99,Cant!$M$2:$M$99,H19,Cant!$J$2:$J$99,"23/1.0"), ""),"")) | J19: =CONCATENATE(F19) | K19: =IF(AND(F19<>"",COUNTIF($F$11:F18,F19)>0),"",IFERROR(IF(AND(J19<>"",SUMIFS(Cant!$I$2:$I$99,Cant!$M$2:$M$99,J19,Cant!$J$2:$J$99,"23/0.8")>0),SUMIFS(Cant!$I$2:$I$99,Cant!$M$2:$M$99,J19,Cant!$J$2:$J$99,"23/0.8"),""),"")) | L19: =CONCATENATE(F19) | M19: =IF(AND(F19<>"",COUNTIF($F$11:F18,F19)>0),"",IFERROR(IF(AND(L19<>"",SUMIFS(Cant!$I$2:$I$99,Cant!$M$2:$M$99,L19,Cant!$J$2:$J$99,"23/2.0")>0),SUMIFS(Cant!$I$2:$I$99,Cant!$M$2:$M$99,L19,Cant!$J$2:$J$99,"23/2.0"),""),"")) | N19: =CONCATENATE(F19) | O19: =IF(AND(F19<>"",COUNTIF($F$11:F18,F19)>0),"",IFERROR(IF(AND(N19<>"",SUMIFS(Cant!$I$2:$I$99,Cant!$M$2:$M$99,N19,Cant!$J$2:$J$99,"43/1.0")+SUMIFS(Cant!$I$2:$I$99,Cant!$M$2:$M$99,N19,Cant!$J$2:$J$99,"43/0.8")+SUMIFS(Cant!$I$2:$I$99,Cant!$M$2:$M$99,N19,Cant!$J$2:$J$99,"42/1.0")>0),SUMIFS(Cant!$I$2:$I$99,Cant!$M$2:$M$99,N19,Cant!$J$2:$J$99,"43/1.0")+SUMIFS(Cant!$I$2:$I$99,Cant!$M$2:$M$99,N19,Cant!$J$2:$J$99,"43/0.8")+SUMIFS(Cant!$I$2:$I$99,Cant!$M$2:$M$99,N19,Cant!$J$2:$J$99,"42/1.0"),""),"")) | P19: =CONCATENATE(F19) | Q19: =IF(AND(F19<>"",COUNTIF($F$11:F18,F19)>0),"",IFERROR(IF(AND(P19<>"",SUMIFS(Cant!$I$2:$I$99,Cant!$M$2:$M$99,P19,Cant!$J$2:$J$99,"43/1.5")+SUMIFS(Cant!$I$2:$I$99,Cant!$M$2:$M$99,P19,Cant!$J$2:$J$99,"24/1.5")>0),SUMIFS(Cant!$I$2:$I$99,Cant!$M$2:$M$99,P19,Cant!$J$2:$J$99,"43/1.5")+SUMIFS(Cant!$I$2:$I$99,Cant!$M$2:$M$99,P19,Cant!$J$2:$J$99,"24/1.5"),""),"")) | R19: =CONCATENATE(F19) | S19: =IF(AND(F19<>"",COUNTIF($F$11:F18,F19)>0),"",IFERROR(IF(AND(R19<>"",SUMIFS(Cant!$I$2:$I$99,Cant!$M$2:$M$99,R19,Cant!$J$2:$J$99,"43/2.0")>0),SUMIFS(Cant!$I$2:$I$99,Cant!$M$2:$M$99,R19,Cant!$J$2:$J$99,"43/2.0"),""),""))
B20: {=IFERROR(_xlfn.SINGLE(INDEX(Deco!$Y$2:$Y$99,_xlfn.AGGREGATE(15,6,ROW(Deco!$Y$2:$Y$99)-ROW(Deco!$Y$2)+1/(Deco!$W$2:$W$99="PAL"),10))),"")} | C20: {=IFERROR( IF(D20="buc", IF(B20<>"", INDEX(Deco!$C$2:$C$99, MATCH(1, (Deco!$Y$2:$Y$99=B20)*(Deco!$W$2:$W$99="PAL"), 0)), ""), IF(AND(B20<>"", INDEX(Deco!$W$2:$W$99, MATCH(1, (Deco!$Y$2:$Y$99=B20)*(Deco!$W$2:$W$99="PAL"), 0))="PAL"), INDEX(Deco!$V$2:$V$99, MATCH(1, (Deco!$Y$2:$Y$99=B20)*(Deco!$W$2:$W$99="PAL"), 0)), "") ), "")} | D20: {=IF(I3="Debitare căntuire", IF(OR(RIGHT(B20,1)={"0","1","2","3","4","5","6","7","8","9"},RIGHT(B20,2)="SM",RIGHT(B20,2)="PM",RIGHT(B20,2)="PG",RIGHT(B20,2)="mm",RIGHT(B20,2)="mp",RIGHT(B20,2)="PA",RIGHT(B20,2)="3D"),"buc","mp"), "mp")} -> mp | F20: {=IFERROR(INDEX(Cant!$M$2:$M$99,_xlfn.AGGREGATE(15,6,(ROW(Cant!$M$2:$M$99)-ROW(Cant!$M$2)+1)/((Cant!$M$2:$M$99<>"")*(COUNTIF($F$10:F19,Cant!$M$2:$M$99)=0)),1)),"")} | G20: =IF(AND(F20<>"",COUNTIF($F$11:F19,F20)>0),"", IFERROR( IF(AND(F20<>"", SUMIFS(Cant!$I$2:$I$99,Cant!$M$2:$M$99,F20,Cant!$J$2:$J$99,"22/0.4") +SUMIFS(Cant!$I$2:$I$99,Cant!$M$2:$M$99,F20,Cant!$J$2:$J$99,"22/0.5")>0), SUMIFS(Cant!$I$2:$I$99,Cant!$M$2:$M$99,F20,Cant!$J$2:$J$99,"22/0.4") +SUMIFS(Cant!$I$2:$I$99,Cant!$M$2:$M$99,F20,Cant!$J$2:$J$99,"22/0.5"), ""), "") ) | H20: =CONCATENATE(F20) | I20: =IF(AND(F20<>"",COUNTIF($F$11:F19,F20)>0),"",IFERROR( IF(AND(H20<>"", SUMIFS(Cant!$I$2:$I$99,Cant!$M$2:$M$99,H20,Cant!$J$2:$J$99,"22/1.0") +SUMIFS(Cant!$I$2:$I$99,Cant!$M$2:$M$99,H20,Cant!$J$2:$J$99,"23/1.0")>0), SUMIFS(Cant!$I$2:$I$99,Cant!$M$2:$M$99,H20,Cant!$J$2:$J$99,"22/1.0") +SUMIFS(Cant!$I$2:$I$99,Cant!$M$2:$M$99,H20,Cant!$J$2:$J$99,"23/1.0"), ""),"")) | J20: =CONCATENATE(F20) | K20: =IF(AND(F20<>"",COUNTIF($F$11:F19,F20)>0),"",IFERROR(IF(AND(J20<>"",SUMIFS(Cant!$I$2:$I$99,Cant!$M$2:$M$99,J20,Cant!$J$2:$J$99,"23/0.8")>0),SUMIFS(Cant!$I$2:$I$99,Cant!$M$2:$M$99,J20,Cant!$J$2:$J$99,"23/0.8"),""),"")) | L20: =CONCATENATE(F20) | M20: =IF(AND(F20<>"",COUNTIF($F$11:F19,F20)>0),"",IFERROR(IF(AND(L20<>"",SUMIFS(Cant!$I$2:$I$99,Cant!$M$2:$M$99,L20,Cant!$J$2:$J$99,"23/2.0")>0),SUMIFS(Cant!$I$2:$I$99,Cant!$M$2:$M$99,L20,Cant!$J$2:$J$99,"23/2.0"),""),"")) | N20: =CONCATENATE(F20) | O20: =IF(AND(F20<>"",COUNTIF($F$11:F19,F20)>0),"",IFERROR(IF(AND(N20<>"",SUMIFS(Cant!$I$2:$I$99,Cant!$M$2:$M$99,N20,Cant!$J$2:$J$99,"43/1.0")+SUMIFS(Cant!$I$2:$I$99,Cant!$M$2:$M$99,N20,Cant!$J$2:$J$99,"43/0.8")+SUMIFS(Cant!$I$2:$I$99,Cant!$M$2:$M$99,N20,Cant!$J$2:$J$99,"42/1.0")>0),SUMIFS(Cant!$I$2:$I$99,Cant!$M$2:$M$99,N20,Cant!$J$2:$J$99,"43/1.0")+SUMIFS(Cant!$I$2:$I$99,Cant!$M$2:$M$99,N20,Cant!$J$2:$J$99,"43/0.8")+SUMIFS(Cant!$I$2:$I$99,Cant!$M$2:$M$99,N20,Cant!$J$2:$J$99,"42/1.0"),""),"")) | P20: =CONCATENATE(F20) | Q20: =IF(AND(F20<>"",COUNTIF($F$11:F19,F20)>0),"",IFERROR(IF(AND(P20<>"",SUMIFS(Cant!$I$2:$I$99,Cant!$M$2:$M$99,P20,Cant!$J$2:$J$99,"43/1.5")+SUMIFS(Cant!$I$2:$I$99,Cant!$M$2:$M$99,P20,Cant!$J$2:$J$99,"24/1.5")>0),SUMIFS(Cant!$I$2:$I$99,Cant!$M$2:$M$99,P20,Cant!$J$2:$J$99,"43/1.5")+SUMIFS(Cant!$I$2:$I$99,Cant!$M$2:$M$99,P20,Cant!$J$2:$J$99,"24/1.5"),""),"")) | R20: =CONCATENATE(F20) | S20: =IF(AND(F20<>"",COUNTIF($F$11:F19,F20)>0),"",IFERROR(IF(AND(R20<>"",SUMIFS(Cant!$I$2:$I$99,Cant!$M$2:$M$99,R20,Cant!$J$2:$J$99,"43/2.0")>0),SUMIFS(Cant!$I$2:$I$99,Cant!$M$2:$M$99,R20,Cant!$J$2:$J$99,"43/2.0"),""),""))
B21: {=IFERROR(_xlfn.SINGLE(INDEX(Deco!$Y$2:$Y$99,_xlfn.AGGREGATE(15,6,ROW(Deco!$Y$2:$Y$99)-ROW(Deco!$Y$2)+1/(Deco!$W$2:$W$99="PAL"),11))),"")} | C21: {=IFERROR( IF(D21="buc", IF(B21<>"", INDEX(Deco!$C$2:$C$99, MATCH(1, (Deco!$Y$2:$Y$99=B21)*(Deco!$W$2:$W$99="PAL"), 0)), ""), IF(AND(B21<>"", INDEX(Deco!$W$2:$W$99, MATCH(1, (Deco!$Y$2:$Y$99=B21)*(Deco!$W$2:$W$99="PAL"), 0))="PAL"), INDEX(Deco!$V$2:$V$99, MATCH(1, (Deco!$Y$2:$Y$99=B21)*(Deco!$W$2:$W$99="PAL"), 0)), "") ), "")} | D21: {=IF(I3="Debitare căntuire", IF(OR(RIGHT(B21,1)={"0","1","2","3","4","5","6","7","8","9"},RIGHT(B21,2)="SM",RIGHT(B21,2)="PM",RIGHT(B21,2)="PG",RIGHT(B21,2)="mm",RIGHT(B21,2)="mp",RIGHT(B21,2)="PA",RIGHT(B21,2)="3D"),"buc","mp"), "mp")} -> mp | F21: {=IFERROR(INDEX(Cant!$M$2:$M$99,_xlfn.AGGREGATE(15,6,(ROW(Cant!$M$2:$M$99)-ROW(Cant!$M$2)+1)/((Cant!$M$2:$M$99<>"")*(COUNTIF($F$10:F20,Cant!$M$2:$M$99)=0)),1)),"")} | G21: =IF(AND(F21<>"",COUNTIF($F$11:F20,F21)>0),"", IFERROR( IF(AND(F21<>"", SUMIFS(Cant!$I$2:$I$99,Cant!$M$2:$M$99,F21,Cant!$J$2:$J$99,"22/0.4") +SUMIFS(Cant!$I$2:$I$99,Cant!$M$2:$M$99,F21,Cant!$J$2:$J$99,"22/0.5")>0), SUMIFS(Cant!$I$2:$I$99,Cant!$M$2:$M$99,F21,Cant!$J$2:$J$99,"22/0.4") +SUMIFS(Cant!$I$2:$I$99,Cant!$M$2:$M$99,F21,Cant!$J$2:$J$99,"22/0.5"), ""), "") ) | H21: =CONCATENATE(F21) | I21: =IF(AND(F21<>"",COUNTIF($F$11:F20,F21)>0),"",IFERROR( IF(AND(H21<>"", SUMIFS(Cant!$I$2:$I$99,Cant!$M$2:$M$99,H21,Cant!$J$2:$J$99,"22/1.0") +SUMIFS(Cant!$I$2:$I$99,Cant!$M$2:$M$99,H21,Cant!$J$2:$J$99,"23/1.0")>0), SUMIFS(Cant!$I$2:$I$99,Cant!$M$2:$M$99,H21,Cant!$J$2:$J$99,"22/1.0") +SUMIFS(Cant!$I$2:$I$99,Cant!$M$2:$M$99,H21,Cant!$J$2:$J$99,"23/1.0"), ""),"")) | J21: =CONCATENATE(F21) | K21: =IF(AND(F21<>"",COUNTIF($F$11:F20,F21)>0),"",IFERROR(IF(AND(J21<>"",SUMIFS(Cant!$I$2:$I$99,Cant!$M$2:$M$99,J21,Cant!$J$2:$J$99,"23/0.8")>0),SUMIFS(Cant!$I$2:$I$99,Cant!$M$2:$M$99,J21,Cant!$J$2:$J$99,"23/0.8"),""),"")) | L21: =CONCATENATE(F21) | M21: =IF(AND(F21<>"",COUNTIF($F$11:F20,F21)>0),"",IFERROR(IF(AND(L21<>"",SUMIFS(Cant!$I$2:$I$99,Cant!$M$2:$M$99,L21,Cant!$J$2:$J$99,"23/2.0")>0),SUMIFS(Cant!$I$2:$I$99,Cant!$M$2:$M$99,L21,Cant!$J$2:$J$99,"23/2.0"),""),"")) | N21: =CONCATENATE(F21) | O21: =IF(AND(F21<>"",COUNTIF($F$11:F20,F21)>0),"",IFERROR(IF(AND(N21<>"",SUMIFS(Cant!$I$2:$I$99,Cant!$M$2:$M$99,N21,Cant!$J$2:$J$99,"43/1.0")+SUMIFS(Cant!$I$2:$I$99,Cant!$M$2:$M$99,N21,Cant!$J$2:$J$99,"43/0.8")+SUMIFS(Cant!$I$2:$I$99,Cant!$M$2:$M$99,N21,Cant!$J$2:$J$99,"42/1.0")>0),SUMIFS(Cant!$I$2:$I$99,Cant!$M$2:$M$99,N21,Cant!$J$2:$J$99,"43/1.0")+SUMIFS(Cant!$I$2:$I$99,Cant!$M$2:$M$99,N21,Cant!$J$2:$J$99,"43/0.8")+SUMIFS(Cant!$I$2:$I$99,Cant!$M$2:$M$99,N21,Cant!$J$2:$J$99,"42/1.0"),""),"")) | P21: =CONCATENATE(F21) | Q21: =IF(AND(F21<>"",COUNTIF($F$11:F20,F21)>0),"",IFERROR(IF(AND(P21<>"",SUMIFS(Cant!$I$2:$I$99,Cant!$M$2:$M$99,P21,Cant!$J$2:$J$99,"43/1.5")+SUMIFS(Cant!$I$2:$I$99,Cant!$M$2:$M$99,P21,Cant!$J$2:$J$99,"24/1.5")>0),SUMIFS(Cant!$I$2:$I$99,Cant!$M$2:$M$99,P21,Cant!$J$2:$J$99,"43/1.5")+SUMIFS(Cant!$I$2:$I$99,Cant!$M$2:$M$99,P21,Cant!$J$2:$J$99,"24/1.5"),""),"")) | R21: =CONCATENATE(F21) | S21: =IF(AND(F21<>"",COUNTIF($F$11:F20,F21)>0),"",IFERROR(IF(AND(R21<>"",SUMIFS(Cant!$I$2:$I$99,Cant!$M$2:$M$99,R21,Cant!$J$2:$J$99,"43/2.0")>0),SUMIFS(Cant!$I$2:$I$99,Cant!$M$2:$M$99,R21,Cant!$J$2:$J$99,"43/2.0"),""),""))
B22: {=IFERROR(_xlfn.SINGLE(INDEX(Deco!$Y$2:$Y$99,_xlfn.AGGREGATE(15,6,ROW(Deco!$Y$2:$Y$99)-ROW(Deco!$Y$2)+1/(Deco!$W$2:$W$99="PAL"),12))),"")} | C22: {=IFERROR( IF(D22="buc", IF(B22<>"", INDEX(Deco!$C$2:$C$99, MATCH(1, (Deco!$Y$2:$Y$99=B22)*(Deco!$W$2:$W$99="PAL"), 0)), ""), IF(AND(B22<>"", INDEX(Deco!$W$2:$W$99, MATCH(1, (Deco!$Y$2:$Y$99=B22)*(Deco!$W$2:$W$99="PAL"), 0))="PAL"), INDEX(Deco!$V$2:$V$99, MATCH(1, (Deco!$Y$2:$Y$99=B22)*(Deco!$W$2:$W$99="PAL"), 0)), "") ), "")} | D22: {=IF(I3="Debitare căntuire", IF(OR(RIGHT(B22,1)={"0","1","2","3","4","5","6","7","8","9"},RIGHT(B22,2)="SM",RIGHT(B22,2)="PM",RIGHT(B22,2)="PG",RIGHT(B22,2)="mm",RIGHT(B22,2)="mp",RIGHT(B22,2)="PA",RIGHT(B22,2)="3D"),"buc","mp"), "mp")} -> mp | F22: {=IFERROR(INDEX(Cant!$M$2:$M$99,_xlfn.AGGREGATE(15,6,(ROW(Cant!$M$2:$M$99)-ROW(Cant!$M$2)+1)/((Cant!$M$2:$M$99<>"")*(COUNTIF($F$10:F21,Cant!$M$2:$M$99)=0)),1)),"")} | G22: =IF(AND(F22<>"",COUNTIF($F$11:F21,F22)>0),"", IFERROR( IF(AND(F22<>"", SUMIFS(Cant!$I$2:$I$99,Cant!$M$2:$M$99,F22,Cant!$J$2:$J$99,"22/0.4") +SUMIFS(Cant!$I$2:$I$99,Cant!$M$2:$M$99,F22,Cant!$J$2:$J$99,"22/0.5")>0), SUMIFS(Cant!$I$2:$I$99,Cant!$M$2:$M$99,F22,Cant!$J$2:$J$99,"22/0.4") +SUMIFS(Cant!$I$2:$I$99,Cant!$M$2:$M$99,F22,Cant!$J$2:$J$99,"22/0.5"), ""), "") ) | H22: =CONCATENATE(F22) | I22: =IF(AND(F22<>"",COUNTIF($F$11:F21,F22)>0),"",IFERROR( IF(AND(H22<>"", SUMIFS(Cant!$I$2:$I$99,Cant!$M$2:$M$99,H22,Cant!$J$2:$J$99,"22/1.0") +SUMIFS(Cant!$I$2:$I$99,Cant!$M$2:$M$99,H22,Cant!$J$2:$J$99,"23/1.0")>0), SUMIFS(Cant!$I$2:$I$99,Cant!$M$2:$M$99,H22,Cant!$J$2:$J$99,"22/1.0") +SUMIFS(Cant!$I$2:$I$99,Cant!$M$2:$M$99,H22,Cant!$J$2:$J$99,"23/1.0"), ""),"")) | J22: =CONCATENATE(F22) | K22: =IF(AND(F22<>"",COUNTIF($F$11:F21,F22)>0),"",IFERROR(IF(AND(J22<>"",SUMIFS(Cant!$I$2:$I$99,Cant!$M$2:$M$99,J22,Cant!$J$2:$J$99,"23/0.8")>0),SUMIFS(Cant!$I$2:$I$99,Cant!$M$2:$M$99,J22,Cant!$J$2:$J$99,"23/0.8"),""),"")) | L22: =CONCATENATE(F22) | M22: =IF(AND(F22<>"",COUNTIF($F$11:F21,F22)>0),"",IFERROR(IF(AND(L22<>"",SUMIFS(Cant!$I$2:$I$99,Cant!$M$2:$M$99,L22,Cant!$J$2:$J$99,"23/2.0")>0),SUMIFS(Cant!$I$2:$I$99,Cant!$M$2:$M$99,L22,Cant!$J$2:$J$99,"23/2.0"),""),"")) | N22: =CONCATENATE(F22) | O22: =IF(AND(F22<>"",COUNTIF($F$11:F21,F22)>0),"",IFERROR(IF(AND(N22<>"",SUMIFS(Cant!$I$2:$I$99,Cant!$M$2:$M$99,N22,Cant!$J$2:$J$99,"43/1.0")+SUMIFS(Cant!$I$2:$I$99,Cant!$M$2:$M$99,N22,Cant!$J$2:$J$99,"43/0.8")+SUMIFS(Cant!$I$2:$I$99,Cant!$M$2:$M$99,N22,Cant!$J$2:$J$99,"42/1.0")>0),SUMIFS(Cant!$I$2:$I$99,Cant!$M$2:$M$99,N22,Cant!$J$2:$J$99,"43/1.0")+SUMIFS(Cant!$I$2:$I$99,Cant!$M$2:$M$99,N22,Cant!$J$2:$J$99,"43/0.8")+SUMIFS(Cant!$I$2:$I$99,Cant!$M$2:$M$99,N22,Cant!$J$2:$J$99,"42/1.0"),""),"")) | P22: =CONCATENATE(F22) | Q22: =IF(AND(F22<>"",COUNTIF($F$11:F21,F22)>0),"",IFERROR(IF(AND(P22<>"",SUMIFS(Cant!$I$2:$I$99,Cant!$M$2:$M$99,P22,Cant!$J$2:$J$99,"43/1.5")+SUMIFS(Cant!$I$2:$I$99,Cant!$M$2:$M$99,P22,Cant!$J$2:$J$99,"24/1.5")>0),SUMIFS(Cant!$I$2:$I$99,Cant!$M$2:$M$99,P22,Cant!$J$2:$J$99,"43/1.5")+SUMIFS(Cant!$I$2:$I$99,Cant!$M$2:$M$99,P22,Cant!$J$2:$J$99,"24/1.5"),""),"")) | R22: =CONCATENATE(F22) | S22: =IF(AND(F22<>"",COUNTIF($F$11:F21,F22)>0),"",IFERROR(IF(AND(R22<>"",SUMIFS(Cant!$I$2:$I$99,Cant!$M$2:$M$99,R22,Cant!$J$2:$J$99,"43/2.0")>0),SUMIFS(Cant!$I$2:$I$99,Cant!$M$2:$M$99,R22,Cant!$J$2:$J$99,"43/2.0"),""),""))
D23: {=IF(I14="Mobilier în Roomdesigner", IF(OR(RIGHT(B23,1)={"0","1","2","3","4","5","6","7","8","9"},RIGHT(B23,2)="SM",RIGHT(B23,2)="PM",RIGHT(B23,2)="PG",RIGHT(B23,2)="mm"),"buc","mp"), "mp")} -> mp | H23: =CONCATENATE(F23) | J23: =CONCATENATE(F23) | L23: =CONCATENATE(F23) | N23: =CONCATENATE(F23) | P23: =CONCATENATE(F23) | R23: =CONCATENATE(F23) | S23: =IF(AND(F23<>"",COUNTIF($F$11:F22,F23)>0),"",IFERROR(IF(AND(R23<>"",SUMIFS(Cant!$I$2:$I$99,Cant!$M$2:$M$99,R23,Cant!$J$2:$J$99,"43/2.0")>0),SUMIFS(Cant!$I$2:$I$99,Cant!$M$2:$M$99,R23,Cant!$J$2:$J$99,"43/2.0"),""),""))
A24: MDF | B24: {=IFERROR(_xlfn.SINGLE(INDEX(Deco!$Y$2:$Y$99,_xlfn.AGGREGATE(15,6,ROW(Deco!$Y$2:$Y$99)-ROW(Deco!$Y$2)+1/(Deco!$W$2:$W$99="MDF"),1))),"")} | C24: {=IFERROR( IF(D24="buc", IF(B24<>"", INDEX(Deco!$C$2:$C$99, MATCH(1, (Deco!$Y$2:$Y$99=B24)*(Deco!$W$2:$W$99="MDF"), 0)), ""), IF(AND(B24<>"", INDEX(Deco!$W$2:$W$99, MATCH(1, (Deco!$Y$2:$Y$99=B24)*(Deco!$W$2:$W$99="MDF"), 0))="MDF"), INDEX(Deco!$V$2:$V$99, MATCH(1, (Deco!$Y$2:$Y$99=B24)*(Deco!$W$2:$W$99="MDF"), 0)), "") ), "")} | D24: {=IF(I3="Debitare căntuire", IF(OR(RIGHT(B24,1)={"0","1","2","3","4","5","6","7","8","9"},RIGHT(B24,2)="SM",RIGHT(B24,2)="PM",RIGHT(B24,2)="PG",RIGHT(B24,2)="mm",RIGHT(B24,2)="mp",RIGHT(B24,2)="PA",RIGHT(B24,2)="3D"),"buc","mp"), "mp")} -> mp | F24: {=IFERROR(INDEX(Cant!$M$2:$M$99,_xlfn.AGGREGATE(15,6,(ROW(Cant!$M$2:$M$99)-ROW(Cant!$M$2)+1)/((Cant!$M$2:$M$99<>"")*(COUNTIF($F$10:F23,Cant!$M$2:$M$99)=0)),1)),"")} | G24: =IF(AND(F24<>"",COUNTIF($F$11:F23,F24)>0),"", IFERROR( IF(AND(F24<>"", SUMIFS(Cant!$I$2:$I$99,Cant!$M$2:$M$99,F24,Cant!$J$2:$J$99,"22/0.4") +SUMIFS(Cant!$I$2:$I$99,Cant!$M$2:$M$99,F24,Cant!$J$2:$J$99,"22/0.5")>0), SUMIFS(Cant!$I$2:$I$99,Cant!$M$2:$M$99,F24,Cant!$J$2:$J$99,"22/0.4") +SUMIFS(Cant!$I$2:$I$99,Cant!$M$2:$M$99,F24,Cant!$J$2:$J$99,"22/0.5"), ""), "") ) | H24: =CONCATENATE(F24) | I24: =IF(AND(F24<>"",COUNTIF($F$11:F23,F24)>0),"",IFERROR( IF(AND(H24<>"", SUMIFS(Cant!$I$2:$I$99,Cant!$M$2:$M$99,H24,Cant!$J$2:$J$99,"22/1.0") +SUMIFS(Cant!$I$2:$I$99,Cant!$M$2:$M$99,H24,Cant!$J$2:$J$99,"23/1.0")>0), SUMIFS(Cant!$I$2:$I$99,Cant!$M$2:$M$99,H24,Cant!$J$2:$J$99,"22/1.0") +SUMIFS(Cant!$I$2:$I$99,Cant!$M$2:$M$99,H24,Cant!$J$2:$J$99,"23/1.0"), ""),"")) | J24: =CONCATENATE(F24) | K24: =IF(AND(F24<>"",COUNTIF($F$11:F23,F24)>0),"",IFERROR(IF(AND(J24<>"",SUMIFS(Cant!$I$2:$I$99,Cant!$M$2:$M$99,J24,Cant!$J$2:$J$99,"23/0.8")>0),SUMIFS(Cant!$I$2:$I$99,Cant!$M$2:$M$99,J24,Cant!$J$2:$J$99,"23/0.8"),""),"")) | L24: =CONCATENATE(F24) | M24: =IF(AND(F24<>"",COUNTIF($F$11:F23,F24)>0),"",IFERROR(IF(AND(L24<>"",SUMIFS(Cant!$I$2:$I$99,Cant!$M$2:$M$99,L24,Cant!$J$2:$J$99,"23/2.0")>0),SUMIFS(Cant!$I$2:$I$99,Cant!$M$2:$M$99,L24,Cant!$J$2:$J$99,"23/2.0"),""),"")) | N24: =CONCATENATE(F24) | O24: =IF(AND(F24<>"",COUNTIF($F$11:F23,F24)>0),"",IFERROR(IF(AND(N24<>"",SUMIFS(Cant!$I$2:$I$99,Cant!$M$2:$M$99,N24,Cant!$J$2:$J$99,"43/1.0")+SUMIFS(Cant!$I$2:$I$99,Cant!$M$2:$M$99,N24,Cant!$J$2:$J$99,"43/0.8")+SUMIFS(Cant!$I$2:$I$99,Cant!$M$2:$M$99,N24,Cant!$J$2:$J$99,"42/1.0")>0),SUMIFS(Cant!$I$2:$I$99,Cant!$M$2:$M$99,N24,Cant!$J$2:$J$99,"43/1.0")+SUMIFS(Cant!$I$2:$I$99,Cant!$M$2:$M$99,N24,Cant!$J$2:$J$99,"43/0.8")+SUMIFS(Cant!$I$2:$I$99,Cant!$M$2:$M$99,N24,Cant!$J$2:$J$99,"42/1.0"),""),"")) | P24: =CONCATENATE(F24) | Q24: =IF(AND(F24<>"",COUNTIF($F$11:F23,F24)>0),"",IFERROR(IF(AND(P24<>"",SUMIFS(Cant!$I$2:$I$99,Cant!$M$2:$M$99,P24,Cant!$J$2:$J$99,"43/1.5")+SUMIFS(Cant!$I$2:$I$99,Cant!$M$2:$M$99,P24,Cant!$J$2:$J$99,"24/1.5")>0),SUMIFS(Cant!$I$2:$I$99,Cant!$M$2:$M$99,P24,Cant!$J$2:$J$99,"43/1.5")+SUMIFS(Cant!$I$2:$I$99,Cant!$M$2:$M$99,P24,Cant!$J$2:$J$99,"24/1.5"),""),"")) | R24: =CONCATENATE(F24) | S24: =IF(AND(F24<>"",COUNTIF($F$11:F23,F24)>0),"",IFERROR(IF(AND(R24<>"",SUMIFS(Cant!$I$2:$I$99,Cant!$M$2:$M$99,R24,Cant!$J$2:$J$99,"43/2.0")>0),SUMIFS(Cant!$I$2:$I$99,Cant!$M$2:$M$99,R24,Cant!$J$2:$J$99,"43/2.0"),""),""))
B25: =IFERROR(INDEX(Deco!$Y$2:$Y$99,_xlfn.AGGREGATE(15,6,ROW(Deco!$Y$2:$Y$99)-ROW(Deco!$Y$2)+1/(Deco!$W$2:$W$99="MDF"),2)),"") | C25: {=IFERROR( IF(D25="buc", IF(B25<>"", INDEX(Deco!$C$2:$C$99, MATCH(1, (Deco!$Y$2:$Y$99=B25)*(Deco!$W$2:$W$99="MDF"), 0)), ""), IF(AND(B25<>"", INDEX(Deco!$W$2:$W$99, MATCH(1, (Deco!$Y$2:$Y$99=B25)*(Deco!$W$2:$W$99="MDF"), 0))="MDF"), INDEX(Deco!$V$2:$V$99, MATCH(1, (Deco!$Y$2:$Y$99=B25)*(Deco!$W$2:$W$99="MDF"), 0)), "") ), "")} | D25: {=IF(I3="Debitare căntuire", IF(OR(RIGHT(B25,1)={"0","1","2","3","4","5","6","7","8","9"},RIGHT(B25,2)="SM",RIGHT(B25,2)="PM",RIGHT(B25,2)="PG",RIGHT(B25,2)="mm",RIGHT(B25,2)="mp",RIGHT(B25,2)="PA",RIGHT(B25,2)="3D"),"buc","mp"), "mp")} -> mp | F25: {=IFERROR(INDEX(Cant!$M$2:$M$99,_xlfn.AGGREGATE(15,6,(ROW(Cant!$M$2:$M$99)-ROW(Cant!$M$2)+1)/((Cant!$M$2:$M$99<>"")*(COUNTIF($F$10:F24,Cant!$M$2:$M$99)=0)),1)),"")} | G25: =IF(AND(F25<>"",COUNTIF($F$11:F24,F25)>0),"", IFERROR( IF(AND(F25<>"", SUMIFS(Cant!$I$2:$I$99,Cant!$M$2:$M$99,F25,Cant!$J$2:$J$99,"22/0.4") +SUMIFS(Cant!$I$2:$I$99,Cant!$M$2:$M$99,F25,Cant!$J$2:$J$99,"22/0.5")>0), SUMIFS(Cant!$I$2:$I$99,Cant!$M$2:$M$99,F25,Cant!$J$2:$J$99,"22/0.4") +SUMIFS(Cant!$I$2:$I$99,Cant!$M$2:$M$99,F25,Cant!$J$2:$J$99,"22/0.5"), ""), "") ) | H25: =CONCATENATE(F25) | I25: =IF(AND(F25<>"",COUNTIF($F$11:F24,F25)>0),"",IFERROR( IF(AND(H25<>"", SUMIFS(Cant!$I$2:$I$99,Cant!$M$2:$M$99,H25,Cant!$J$2:$J$99,"22/1.0") +SUMIFS(Cant!$I$2:$I$99,Cant!$M$2:$M$99,H25,Cant!$J$2:$J$99,"23/1.0")>0), SUMIFS(Cant!$I$2:$I$99,Cant!$M$2:$M$99,H25,Cant!$J$2:$J$99,"22/1.0") +SUMIFS(Cant!$I$2:$I$99,Cant!$M$2:$M$99,H25,Cant!$J$2:$J$99,"23/1.0"), ""),"")) | J25: =CONCATENATE(F25) | K25: =IF(AND(F25<>"",COUNTIF($F$11:F24,F25)>0),"",IFERROR(IF(AND(J25<>"",SUMIFS(Cant!$I$2:$I$99,Cant!$M$2:$M$99,J25,Cant!$J$2:$J$99,"23/0.8")>0),SUMIFS(Cant!$I$2:$I$99,Cant!$M$2:$M$99,J25,Cant!$J$2:$J$99,"23/0.8"),""),"")) | L25: =CONCATENATE(F25) | M25: =IF(AND(F25<>"",COUNTIF($F$11:F24,F25)>0),"",IFERROR(IF(AND(L25<>"",SUMIFS(Cant!$I$2:$I$99,Cant!$M$2:$M$99,L25,Cant!$J$2:$J$99,"23/2.0")>0),SUMIFS(Cant!$I$2:$I$99,Cant!$M$2:$M$99,L25,Cant!$J$2:$J$99,"23/2.0"),""),"")) | N25: =CONCATENATE(F25) | O25: =IF(AND(F25<>"",COUNTIF($F$11:F24,F25)>0),"",IFERROR(IF(AND(N25<>"",SUMIFS(Cant!$I$2:$I$99,Cant!$M$2:$M$99,N25,Cant!$J$2:$J$99,"43/1.0")+SUMIFS(Cant!$I$2:$I$99,Cant!$M$2:$M$99,N25,Cant!$J$2:$J$99,"43/0.8")+SUMIFS(Cant!$I$2:$I$99,Cant!$M$2:$M$99,N25,Cant!$J$2:$J$99,"42/1.0")>0),SUMIFS(Cant!$I$2:$I$99,Cant!$M$2:$M$99,N25,Cant!$J$2:$J$99,"43/1.0")+SUMIFS(Cant!$I$2:$I$99,Cant!$M$2:$M$99,N25,Cant!$J$2:$J$99,"43/0.8")+SUMIFS(Cant!$I$2:$I$99,Cant!$M$2:$M$99,N25,Cant!$J$2:$J$99,"42/1.0"),""),"")) | P25: =CONCATENATE(F25) | Q25: =IF(AND(F25<>"",COUNTIF($F$11:F24,F25)>0),"",IFERROR(IF(AND(P25<>"",SUMIFS(Cant!$I$2:$I$99,Cant!$M$2:$M$99,P25,Cant!$J$2:$J$99,"43/1.5")+SUMIFS(Cant!$I$2:$I$99,Cant!$M$2:$M$99,P25,Cant!$J$2:$J$99,"24/1.5")>0),SUMIFS(Cant!$I$2:$I$99,Cant!$M$2:$M$99,P25,Cant!$J$2:$J$99,"43/1.5")+SUMIFS(Cant!$I$2:$I$99,Cant!$M$2:$M$99,P25,Cant!$J$2:$J$99,"24/1.5"),""),"")) | R25: =CONCATENATE(F25) | S25: =IF(AND(F25<>"",COUNTIF($F$11:F24,F25)>0),"",IFERROR(IF(AND(R25<>"",SUMIFS(Cant!$I$2:$I$99,Cant!$M$2:$M$99,R25,Cant!$J$2:$J$99,"43/2.0")>0),SUMIFS(Cant!$I$2:$I$99,Cant!$M$2:$M$99,R25,Cant!$J$2:$J$99,"43/2.0"),""),""))
B26: {=IFERROR(_xlfn.SINGLE(INDEX(Deco!$Y$2:$Y$99,_xlfn.AGGREGATE(15,6,ROW(Deco!$Y$2:$Y$99)-ROW(Deco!$Y$2)+1/(Deco!$W$2:$W$99="MDF"),3))),"")} | C26: {=IFERROR( IF(D26="buc", IF(B26<>"", INDEX(Deco!$C$2:$C$99, MATCH(1, (Deco!$Y$2:$Y$99=B26)*(Deco!$W$2:$W$99="MDF"), 0)), ""), IF(AND(B26<>"", INDEX(Deco!$W$2:$W$99, MATCH(1, (Deco!$Y$2:$Y$99=B26)*(Deco!$W$2:$W$99="MDF"), 0))="MDF"), INDEX(Deco!$V$2:$V$99, MATCH(1, (Deco!$Y$2:$Y$99=B26)*(Deco!$W$2:$W$99="MDF"), 0)), "") ), "")} | D26: {=IF(I3="Debitare căntuire", IF(OR(RIGHT(B26,1)={"0","1","2","3","4","5","6","7","8","9"},RIGHT(B26,2)="SM",RIGHT(B26,2)="PM",RIGHT(B26,2)="PG",RIGHT(B26,2)="mm",RIGHT(B26,2)="mp",RIGHT(B26,2)="PA",RIGHT(B26,2)="3D"),"buc","mp"), "mp")} -> mp | F26: {=IFERROR(INDEX(Cant!$M$2:$M$99,_xlfn.AGGREGATE(15,6,(ROW(Cant!$M$2:$M$99)-ROW(Cant!$M$2)+1)/((Cant!$M$2:$M$99<>"")*(COUNTIF($F$10:F25,Cant!$M$2:$M$99)=0)),1)),"")} | G26: =IF(AND(F26<>"",COUNTIF($F$11:F25,F26)>0),"", IFERROR( IF(AND(F26<>"", SUMIFS(Cant!$I$2:$I$99,Cant!$M$2:$M$99,F26,Cant!$J$2:$J$99,"22/0.4") +SUMIFS(Cant!$I$2:$I$99,Cant!$M$2:$M$99,F26,Cant!$J$2:$J$99,"22/0.5")>0), SUMIFS(Cant!$I$2:$I$99,Cant!$M$2:$M$99,F26,Cant!$J$2:$J$99,"22/0.4") +SUMIFS(Cant!$I$2:$I$99,Cant!$M$2:$M$99,F26,Cant!$J$2:$J$99,"22/0.5"), ""), "") ) | H26: =CONCATENATE(F26) | I26: =IF(AND(F26<>"",COUNTIF($F$11:F25,F26)>0),"",IFERROR( IF(AND(H26<>"", SUMIFS(Cant!$I$2:$I$99,Cant!$M$2:$M$99,H26,Cant!$J$2:$J$99,"22/1.0") +SUMIFS(Cant!$I$2:$I$99,Cant!$M$2:$M$99,H26,Cant!$J$2:$J$99,"23/1.0")>0), SUMIFS(Cant!$I$2:$I$99,Cant!$M$2:$M$99,H26,Cant!$J$2:$J$99,"22/1.0") +SUMIFS(Cant!$I$2:$I$99,Cant!$M$2:$M$99,H26,Cant!$J$2:$J$99,"23/1.0"), ""),"")) | J26: =CONCATENATE(F26) | K26: =IF(AND(F26<>"",COUNTIF($F$11:F25,F26)>0),"",IFERROR(IF(AND(J26<>"",SUMIFS(Cant!$I$2:$I$99,Cant!$M$2:$M$99,J26,Cant!$J$2:$J$99,"23/0.8")>0),SUMIFS(Cant!$I$2:$I$99,Cant!$M$2:$M$99,J26,Cant!$J$2:$J$99,"23/0.8"),""),"")) | L26: =CONCATENATE(F26) | M26: =IF(AND(F26<>"",COUNTIF($F$11:F25,F26)>0),"",IFERROR(IF(AND(L26<>"",SUMIFS(Cant!$I$2:$I$99,Cant!$M$2:$M$99,L26,Cant!$J$2:$J$99,"23/2.0")>0),SUMIFS(Cant!$I$2:$I$99,Cant!$M$2:$M$99,L26,Cant!$J$2:$J$99,"23/2.0"),""),"")) | N26: =CONCATENATE(F26) | O26: =IF(AND(F26<>"",COUNTIF($F$11:F25,F26)>0),"",IFERROR(IF(AND(N26<>"",SUMIFS(Cant!$I$2:$I$99,Cant!$M$2:$M$99,N26,Cant!$J$2:$J$99,"43/1.0")+SUMIFS(Cant!$I$2:$I$99,Cant!$M$2:$M$99,N26,Cant!$J$2:$J$99,"43/0.8")+SUMIFS(Cant!$I$2:$I$99,Cant!$M$2:$M$99,N26,Cant!$J$2:$J$99,"42/1.0")>0),SUMIFS(Cant!$I$2:$I$99,Cant!$M$2:$M$99,N26,Cant!$J$2:$J$99,"43/1.0")+SUMIFS(Cant!$I$2:$I$99,Cant!$M$2:$M$99,N26,Cant!$J$2:$J$99,"43/0.8")+SUMIFS(Cant!$I$2:$I$99,Cant!$M$2:$M$99,N26,Cant!$J$2:$J$99,"42/1.0"),""),"")) | P26: =CONCATENATE(F26) | Q26: =IF(AND(F26<>"",COUNTIF($F$11:F25,F26)>0),"",IFERROR(IF(AND(P26<>"",SUMIFS(Cant!$I$2:$I$99,Cant!$M$2:$M$99,P26,Cant!$J$2:$J$99,"43/1.5")+SUMIFS(Cant!$I$2:$I$99,Cant!$M$2:$M$99,P26,Cant!$J$2:$J$99,"24/1.5")>0),SUMIFS(Cant!$I$2:$I$99,Cant!$M$2:$M$99,P26,Cant!$J$2:$J$99,"43/1.5")+SUMIFS(Cant!$I$2:$I$99,Cant!$M$2:$M$99,P26,Cant!$J$2:$J$99,"24/1.5"),""),"")) | R26: =CONCATENATE(F26) | S26: =IF(AND(F26<>"",COUNTIF($F$11:F25,F26)>0),"",IFERROR(IF(AND(R26<>"",SUMIFS(Cant!$I$2:$I$99,Cant!$M$2:$M$99,R26,Cant!$J$2:$J$99,"43/2.0")>0),SUMIFS(Cant!$I$2:$I$99,Cant!$M$2:$M$99,R26,Cant!$J$2:$J$99,"43/2.0"),""),""))
B27: {=IFERROR(_xlfn.SINGLE(INDEX(Deco!$Y$2:$Y$99,_xlfn.AGGREGATE(15,6,ROW(Deco!$Y$2:$Y$99)-ROW(Deco!$Y$2)+1/(Deco!$W$2:$W$99="MDF"),4))),"")} | C27: {=IFERROR( IF(D27="buc", IF(B27<>"", INDEX(Deco!$C$2:$C$99, MATCH(1, (Deco!$Y$2:$Y$99=B27)*(Deco!$W$2:$W$99="MDF"), 0)), ""), IF(AND(B27<>"", INDEX(Deco!$W$2:$W$99, MATCH(1, (Deco!$Y$2:$Y$99=B27)*(Deco!$W$2:$W$99="MDF"), 0))="MDF"), INDEX(Deco!$V$2:$V$99, MATCH(1, (Deco!$Y$2:$Y$99=B27)*(Deco!$W$2:$W$99="MDF"), 0)), "") ), "")} | D27: {=IF(I3="Debitare căntuire", IF(OR(RIGHT(B27,1)={"0","1","2","3","4","5","6","7","8","9"},RIGHT(B27,2)="SM",RIGHT(B27,2)="PM",RIGHT(B27,2)="PG",RIGHT(B27,2)="mm",RIGHT(B27,2)="mp",RIGHT(B27,2)="PA",RIGHT(B27,2)="3D"),"buc","mp"), "mp")} -> mp | F27: {=IFERROR(INDEX(Cant!$M$2:$M$99,_xlfn.AGGREGATE(15,6,(ROW(Cant!$M$2:$M$99)-ROW(Cant!$M$2)+1)/((Cant!$M$2:$M$99<>"")*(COUNTIF($F$10:F26,Cant!$M$2:$M$99)=0)),1)),"")} | G27: =IF(AND(F27<>"",COUNTIF($F$11:F26,F27)>0),"", IFERROR( IF(AND(F27<>"", SUMIFS(Cant!$I$2:$I$99,Cant!$M$2:$M$99,F27,Cant!$J$2:$J$99,"22/0.4") +SUMIFS(Cant!$I$2:$I$99,Cant!$M$2:$M$99,F27,Cant!$J$2:$J$99,"22/0.5")>0), SUMIFS(Cant!$I$2:$I$99,Cant!$M$2:$M$99,F27,Cant!$J$2:$J$99,"22/0.4") +SUMIFS(Cant!$I$2:$I$99,Cant!$M$2:$M$99,F27,Cant!$J$2:$J$99,"22/0.5"), ""), "") ) | H27: =CONCATENATE(F27) | I27: =IF(AND(F27<>"",COUNTIF($F$11:F26,F27)>0),"",IFERROR( IF(AND(H27<>"", SUMIFS(Cant!$I$2:$I$99,Cant!$M$2:$M$99,H27,Cant!$J$2:$J$99,"22/1.0") +SUMIFS(Cant!$I$2:$I$99,Cant!$M$2:$M$99,H27,Cant!$J$2:$J$99,"23/1.0")>0), SUMIFS(Cant!$I$2:$I$99,Cant!$M$2:$M$99,H27,Cant!$J$2:$J$99,"22/1.0") +SUMIFS(Cant!$I$2:$I$99,Cant!$M$2:$M$99,H27,Cant!$J$2:$J$99,"23/1.0"), ""),"")) | J27: =CONCATENATE(F27) | K27: =IF(AND(F27<>"",COUNTIF($F$11:F26,F27)>0),"",IFERROR(IF(AND(J27<>"",SUMIFS(Cant!$I$2:$I$99,Cant!$M$2:$M$99,J27,Cant!$J$2:$J$99,"23/0.8")>0),SUMIFS(Cant!$I$2:$I$99,Cant!$M$2:$M$99,J27,Cant!$J$2:$J$99,"23/0.8"),""),"")) | L27: =CONCATENATE(F27) | M27: =IF(AND(F27<>"",COUNTIF($F$11:F26,F27)>0),"",IFERROR(IF(AND(L27<>"",SUMIFS(Cant!$I$2:$I$99,Cant!$M$2:$M$99,L27,Cant!$J$2:$J$99,"23/2.0")>0),SUMIFS(Cant!$I$2:$I$99,Cant!$M$2:$M$99,L27,Cant!$J$2:$J$99,"23/2.0"),""),"")) | N27: =CONCATENATE(F27) | O27: =IF(AND(F27<>"",COUNTIF($F$11:F26,F27)>0),"",IFERROR(IF(AND(N27<>"",SUMIFS(Cant!$I$2:$I$99,Cant!$M$2:$M$99,N27,Cant!$J$2:$J$99,"43/1.0")+SUMIFS(Cant!$I$2:$I$99,Cant!$M$2:$M$99,N27,Cant!$J$2:$J$99,"43/0.8")+SUMIFS(Cant!$I$2:$I$99,Cant!$M$2:$M$99,N27,Cant!$J$2:$J$99,"42/1.0")>0),SUMIFS(Cant!$I$2:$I$99,Cant!$M$2:$M$99,N27,Cant!$J$2:$J$99,"43/1.0")+SUMIFS(Cant!$I$2:$I$99,Cant!$M$2:$M$99,N27,Cant!$J$2:$J$99,"43/0.8")+SUMIFS(Cant!$I$2:$I$99,Cant!$M$2:$M$99,N27,Cant!$J$2:$J$99,"42/1.0"),""),"")) | P27: =CONCATENATE(F27) | Q27: =IF(AND(F27<>"",COUNTIF($F$11:F26,F27)>0),"",IFERROR(IF(AND(P27<>"",SUMIFS(Cant!$I$2:$I$99,Cant!$M$2:$M$99,P27,Cant!$J$2:$J$99,"43/1.5")+SUMIFS(Cant!$I$2:$I$99,Cant!$M$2:$M$99,P27,Cant!$J$2:$J$99,"24/1.5")>0),SUMIFS(Cant!$I$2:$I$99,Cant!$M$2:$M$99,P27,Cant!$J$2:$J$99,"43/1.5")+SUMIFS(Cant!$I$2:$I$99,Cant!$M$2:$M$99,P27,Cant!$J$2:$J$99,"24/1.5"),""),"")) | R27: =CONCATENATE(F27) | S27: =IF(AND(F27<>"",COUNTIF($F$11:F26,F27)>0),"",IFERROR(IF(AND(R27<>"",SUMIFS(Cant!$I$2:$I$99,Cant!$M$2:$M$99,R27,Cant!$J$2:$J$99,"43/2.0")>0),SUMIFS(Cant!$I$2:$I$99,Cant!$M$2:$M$99,R27,Cant!$J$2:$J$99,"43/2.0"),""),""))
B28: {=IFERROR(_xlfn.SINGLE(INDEX(Deco!$Y$2:$Y$99,_xlfn.AGGREGATE(15,6,ROW(Deco!$Y$2:$Y$99)-ROW(Deco!$Y$2)+1/(Deco!$W$2:$W$99="MDF"),5))),"")} | C28: {=IFERROR( IF(D28="buc", IF(B28<>"", INDEX(Deco!$C$2:$C$99, MATCH(1, (Deco!$Y$2:$Y$99=B28)*(Deco!$W$2:$W$99="MDF"), 0)), ""), IF(AND(B28<>"", INDEX(Deco!$W$2:$W$99, MATCH(1, (Deco!$Y$2:$Y$99=B28)*(Deco!$W$2:$W$99="MDF"), 0))="MDF"), INDEX(Deco!$V$2:$V$99, MATCH(1, (Deco!$Y$2:$Y$99=B28)*(Deco!$W$2:$W$99="MDF"), 0)), "") ), "")} | D28: {=IF(I3="Debitare căntuire", IF(OR(RIGHT(B28,1)={"0","1","2","3","4","5","6","7","8","9"},RIGHT(B28,2)="SM",RIGHT(B28,2)="PM",RIGHT(B28,2)="PG",RIGHT(B28,2)="mm",RIGHT(B28,2)="mp",RIGHT(B28,2)="PA",RIGHT(B28,2)="3D"),"buc","mp"), "mp")} -> mp | F28: {=IFERROR(INDEX(Cant!$M$2:$M$99,_xlfn.AGGREGATE(15,6,(ROW(Cant!$M$2:$M$99)-ROW(Cant!$M$2)+1)/((Cant!$M$2:$M$99<>"")*(COUNTIF($F$10:F27,Cant!$M$2:$M$99)=0)),1)),"")} | G28: =IF(AND(F28<>"",COUNTIF($F$11:F27,F28)>0),"", IFERROR( IF(AND(F28<>"", SUMIFS(Cant!$I$2:$I$99,Cant!$M$2:$M$99,F28,Cant!$J$2:$J$99,"22/0.4") +SUMIFS(Cant!$I$2:$I$99,Cant!$M$2:$M$99,F28,Cant!$J$2:$J$99,"22/0.5")>0), SUMIFS(Cant!$I$2:$I$99,Cant!$M$2:$M$99,F28,Cant!$J$2:$J$99,"22/0.4") +SUMIFS(Cant!$I$2:$I$99,Cant!$M$2:$M$99,F28,Cant!$J$2:$J$99,"22/0.5"), ""), "") ) | H28: =CONCATENATE(F28) | I28: =IF(AND(F28<>"",COUNTIF($F$11:F27,F28)>0),"",IFERROR( IF(AND(H28<>"", SUMIFS(Cant!$I$2:$I$99,Cant!$M$2:$M$99,H28,Cant!$J$2:$J$99,"22/1.0") +SUMIFS(Cant!$I$2:$I$99,Cant!$M$2:$M$99,H28,Cant!$J$2:$J$99,"23/1.0")>0), SUMIFS(Cant!$I$2:$I$99,Cant!$M$2:$M$99,H28,Cant!$J$2:$J$99,"22/1.0") +SUMIFS(Cant!$I$2:$I$99,Cant!$M$2:$M$99,H28,Cant!$J$2:$J$99,"23/1.0"), ""),"")) | J28: =CONCATENATE(F28) | K28: =IF(AND(F28<>"",COUNTIF($F$11:F27,F28)>0),"",IFERROR(IF(AND(J28<>"",SUMIFS(Cant!$I$2:$I$99,Cant!$M$2:$M$99,J28,Cant!$J$2:$J$99,"23/0.8")>0),SUMIFS(Cant!$I$2:$I$99,Cant!$M$2:$M$99,J28,Cant!$J$2:$J$99,"23/0.8"),""),"")) | L28: =CONCATENATE(F28) | M28: =IF(AND(F28<>"",COUNTIF($F$11:F27,F28)>0),"",IFERROR(IF(AND(L28<>"",SUMIFS(Cant!$I$2:$I$99,Cant!$M$2:$M$99,L28,Cant!$J$2:$J$99,"23/2.0")>0),SUMIFS(Cant!$I$2:$I$99,Cant!$M$2:$M$99,L28,Cant!$J$2:$J$99,"23/2.0"),""),"")) | N28: =CONCATENATE(F28) | O28: =IF(AND(F28<>"",COUNTIF($F$11:F27,F28)>0),"",IFERROR(IF(AND(N28<>"",SUMIFS(Cant!$I$2:$I$99,Cant!$M$2:$M$99,N28,Cant!$J$2:$J$99,"43/1.0")+SUMIFS(Cant!$I$2:$I$99,Cant!$M$2:$M$99,N28,Cant!$J$2:$J$99,"43/0.8")+SUMIFS(Cant!$I$2:$I$99,Cant!$M$2:$M$99,N28,Cant!$J$2:$J$99,"42/1.0")>0),SUMIFS(Cant!$I$2:$I$99,Cant!$M$2:$M$99,N28,Cant!$J$2:$J$99,"43/1.0")+SUMIFS(Cant!$I$2:$I$99,Cant!$M$2:$M$99,N28,Cant!$J$2:$J$99,"43/0.8")+SUMIFS(Cant!$I$2:$I$99,Cant!$M$2:$M$99,N28,Cant!$J$2:$J$99,"42/1.0"),""),"")) | P28: =CONCATENATE(F28) | Q28: =IF(AND(F28<>"",COUNTIF($F$11:F27,F28)>0),"",IFERROR(IF(AND(P28<>"",SUMIFS(Cant!$I$2:$I$99,Cant!$M$2:$M$99,P28,Cant!$J$2:$J$99,"43/1.5")+SUMIFS(Cant!$I$2:$I$99,Cant!$M$2:$M$99,P28,Cant!$J$2:$J$99,"24/1.5")>0),SUMIFS(Cant!$I$2:$I$99,Cant!$M$2:$M$99,P28,Cant!$J$2:$J$99,"43/1.5")+SUMIFS(Cant!$I$2:$I$99,Cant!$M$2:$M$99,P28,Cant!$J$2:$J$99,"24/1.5"),""),"")) | R28: =CONCATENATE(F28) | S28: =IF(AND(F28<>"",COUNTIF($F$11:F27,F28)>0),"",IFERROR(IF(AND(R28<>"",SUMIFS(Cant!$I$2:$I$99,Cant!$M$2:$M$99,R28,Cant!$J$2:$J$99,"43/2.0")>0),SUMIFS(Cant!$I$2:$I$99,Cant!$M$2:$M$99,R28,Cant!$J$2:$J$99,"43/2.0"),""),""))
D29: {=IF(I20="Mobilier în Roomdesigner", IF(OR(RIGHT(B29,1)={"0","1","2","3","4","5","6","7","8","9"},RIGHT(B29,2)="SM",RIGHT(B29,2)="PM",RIGHT(B29,2)="PG",RIGHT(B29,2)="mm"),"buc","mp"), "mp")} -> mp | H29: =CONCATENATE(F29) | J29: =CONCATENATE(F29) | L29: =CONCATENATE(F29) | N29: =CONCATENATE(F29) | P29: =CONCATENATE(F29) | R29: =CONCATENATE(F29)
A30: PFL SUBȚIRE | B30: {=IFERROR(_xlfn.SINGLE(INDEX(Deco!$Y$2:$Y$99,_xlfn.AGGREGATE(15,6,ROW(Deco!$Y$2:$Y$99)-ROW(Deco!$Y$2)+1/(Deco!$W$2:$W$99="HDF"),1))),"")} | C30: =IF(D30="buc",IF(B30<>"",INDEX(Deco!$C$2:$C$99,MATCH(B30,Deco!$Y$2:$Y$99,0)),""),IF(B30<>"",INDEX(Deco!$V$2:$V$99,MATCH(B30,Deco!$Y$2:$Y$99,0)),"")) | D30: =IF(I3="Debitare căntuire", "buc", "mp") -> mp | H30: =CONCATENATE(F30) | J30: =CONCATENATE(F30) | L30: =CONCATENATE(F30) | N30: =CONCATENATE(F30) | P30: =CONCATENATE(F30) | R30: =CONCATENATE(F30)
H31: =CONCATENATE(F31) | J31: =CONCATENATE(F31) | L31: =CONCATENATE(F31) | N31: =CONCATENATE(F31) | P31: =CONCATENATE(F31) | R31: =CONCATENATE(F31)
